

25/May/2023 21:04:57,897 [ERROR] django.request: [35;1m[35;1mInternal Server Error: /handler/image-upload[0m[0m
Traceback (most recent call last):
  File "/Users/chaelee/anaconda3/envs/syu_capstone_2022_1_2/lib/python3.9/site-packages/django/utils/datastructures.py", line 84, in __getitem__
    list_ = super().__getitem__(key)
KeyError: 'image'

During handling of the above exception, another exception occurred:

Traceback (most recent call last):
  File "/Users/chaelee/PycharmProjects/syu_capstone_2022_1_2/BloomingMind/Handler/views.py", line 46, in post
    if request.FILES['image']:
  File "/Users/chaelee/anaconda3/envs/syu_capstone_2022_1_2/lib/python3.9/site-packages/django/utils/datastructures.py", line 86, in __getitem__
    raise MultiValueDictKeyError(key)
django.utils.datastructures.MultiValueDictKeyError: 'image'

During handling of the above exception, another exception occurred:

Traceback (most recent call last):
  File "/Users/chaelee/anaconda3/envs/syu_capstone_2022_1_2/lib/python3.9/site-packages/asgiref/sync.py", line 486, in thread_handler
    raise exc_info[1]
  File "/Users/chaelee/anaconda3/envs/syu_capstone_2022_1_2/lib/python3.9/site-packages/django/core/handlers/exception.py", line 42, in inner
    response = await get_response(request)
  File "/Users/chaelee/anaconda3/envs/syu_capstone_2022_1_2/lib/python3.9/site-packages/django/core/handlers/base.py", line 253, in _get_response_async
    response = await wrapped_callback(
  File "/Users/chaelee/anaconda3/envs/syu_capstone_2022_1_2/lib/python3.9/site-packages/asgiref/sync.py", line 448, in __call__
    ret = await asyncio.wait_for(future, timeout=None)
  File "/Users/chaelee/anaconda3/envs/syu_capstone_2022_1_2/lib/python3.9/asyncio/tasks.py", line 442, in wait_for
    return await fut
  File "/Users/chaelee/anaconda3/envs/syu_capstone_2022_1_2/lib/python3.9/site-packages/asgiref/current_thread_executor.py", line 22, in run
    result = self.fn(*self.args, **self.kwargs)
  File "/Users/chaelee/anaconda3/envs/syu_capstone_2022_1_2/lib/python3.9/site-packages/asgiref/sync.py", line 490, in thread_handler
    return func(*args, **kwargs)
  File "/Users/chaelee/anaconda3/envs/syu_capstone_2022_1_2/lib/python3.9/site-packages/django/views/generic/base.py", line 104, in view
    return self.dispatch(request, *args, **kwargs)
  File "/Users/chaelee/anaconda3/envs/syu_capstone_2022_1_2/lib/python3.9/site-packages/django/views/generic/base.py", line 143, in dispatch
    return handler(request, *args, **kwargs)
  File "/Users/chaelee/anaconda3/envs/syu_capstone_2022_1_2/lib/python3.9/site-packages/django/views/decorators/csrf.py", line 56, in wrapper_view
    return view_func(*args, **kwargs)
  File "/Users/chaelee/PycharmProjects/syu_capstone_2022_1_2/BloomingMind/Handler/views.py", line 62, in post
    return JsonResponse(
  File "/Users/chaelee/anaconda3/envs/syu_capstone_2022_1_2/lib/python3.9/site-packages/django/http/response.py", line 748, in __init__
    data = json.dumps(data, cls=encoder, **json_dumps_params)
  File "/Users/chaelee/anaconda3/envs/syu_capstone_2022_1_2/lib/python3.9/json/__init__.py", line 234, in dumps
    return cls(
  File "/Users/chaelee/anaconda3/envs/syu_capstone_2022_1_2/lib/python3.9/json/encoder.py", line 199, in encode
    chunks = self.iterencode(o, _one_shot=True)
  File "/Users/chaelee/anaconda3/envs/syu_capstone_2022_1_2/lib/python3.9/json/encoder.py", line 257, in iterencode
    return _iterencode(o, 0)
  File "/Users/chaelee/anaconda3/envs/syu_capstone_2022_1_2/lib/python3.9/site-packages/django/core/serializers/json.py", line 106, in default
    return super().default(o)
  File "/Users/chaelee/anaconda3/envs/syu_capstone_2022_1_2/lib/python3.9/json/encoder.py", line 179, in default
    raise TypeError(f'Object of type {o.__class__.__name__} '
TypeError: Object of type set is not JSON serializable


25/May/2023 21:05:36,334 [ERROR] django.request: [35;1m[35;1mInternal Server Error: /handler/image-upload[0m[0m
Traceback (most recent call last):
  File "/Users/chaelee/anaconda3/envs/syu_capstone_2022_1_2/lib/python3.9/site-packages/django/utils/datastructures.py", line 84, in __getitem__
    list_ = super().__getitem__(key)
KeyError: 'image'

During handling of the above exception, another exception occurred:

Traceback (most recent call last):
  File "/Users/chaelee/PycharmProjects/syu_capstone_2022_1_2/BloomingMind/Handler/views.py", line 46, in post
    if request.FILES['image']:
  File "/Users/chaelee/anaconda3/envs/syu_capstone_2022_1_2/lib/python3.9/site-packages/django/utils/datastructures.py", line 86, in __getitem__
    raise MultiValueDictKeyError(key)
django.utils.datastructures.MultiValueDictKeyError: 'image'

During handling of the above exception, another exception occurred:

Traceback (most recent call last):
  File "/Users/chaelee/anaconda3/envs/syu_capstone_2022_1_2/lib/python3.9/site-packages/asgiref/sync.py", line 486, in thread_handler
    raise exc_info[1]
  File "/Users/chaelee/anaconda3/envs/syu_capstone_2022_1_2/lib/python3.9/site-packages/django/core/handlers/exception.py", line 42, in inner
    response = await get_response(request)
  File "/Users/chaelee/anaconda3/envs/syu_capstone_2022_1_2/lib/python3.9/site-packages/django/core/handlers/base.py", line 253, in _get_response_async
    response = await wrapped_callback(
  File "/Users/chaelee/anaconda3/envs/syu_capstone_2022_1_2/lib/python3.9/site-packages/asgiref/sync.py", line 448, in __call__
    ret = await asyncio.wait_for(future, timeout=None)
  File "/Users/chaelee/anaconda3/envs/syu_capstone_2022_1_2/lib/python3.9/asyncio/tasks.py", line 442, in wait_for
    return await fut
  File "/Users/chaelee/anaconda3/envs/syu_capstone_2022_1_2/lib/python3.9/site-packages/asgiref/current_thread_executor.py", line 22, in run
    result = self.fn(*self.args, **self.kwargs)
  File "/Users/chaelee/anaconda3/envs/syu_capstone_2022_1_2/lib/python3.9/site-packages/asgiref/sync.py", line 490, in thread_handler
    return func(*args, **kwargs)
  File "/Users/chaelee/anaconda3/envs/syu_capstone_2022_1_2/lib/python3.9/site-packages/django/views/generic/base.py", line 104, in view
    return self.dispatch(request, *args, **kwargs)
  File "/Users/chaelee/anaconda3/envs/syu_capstone_2022_1_2/lib/python3.9/site-packages/django/views/generic/base.py", line 143, in dispatch
    return handler(request, *args, **kwargs)
  File "/Users/chaelee/anaconda3/envs/syu_capstone_2022_1_2/lib/python3.9/site-packages/django/views/decorators/csrf.py", line 56, in wrapper_view
    return view_func(*args, **kwargs)
  File "/Users/chaelee/PycharmProjects/syu_capstone_2022_1_2/BloomingMind/Handler/views.py", line 62, in post
    return JsonResponse(
  File "/Users/chaelee/anaconda3/envs/syu_capstone_2022_1_2/lib/python3.9/site-packages/django/http/response.py", line 748, in __init__
    data = json.dumps(data, cls=encoder, **json_dumps_params)
  File "/Users/chaelee/anaconda3/envs/syu_capstone_2022_1_2/lib/python3.9/json/__init__.py", line 234, in dumps
    return cls(
  File "/Users/chaelee/anaconda3/envs/syu_capstone_2022_1_2/lib/python3.9/json/encoder.py", line 199, in encode
    chunks = self.iterencode(o, _one_shot=True)
  File "/Users/chaelee/anaconda3/envs/syu_capstone_2022_1_2/lib/python3.9/json/encoder.py", line 257, in iterencode
    return _iterencode(o, 0)
  File "/Users/chaelee/anaconda3/envs/syu_capstone_2022_1_2/lib/python3.9/site-packages/django/core/serializers/json.py", line 106, in default
    return super().default(o)
  File "/Users/chaelee/anaconda3/envs/syu_capstone_2022_1_2/lib/python3.9/json/encoder.py", line 179, in default
    raise TypeError(f'Object of type {o.__class__.__name__} '
TypeError: Object of type set is not JSON serializable


25/May/2023 21:06:29,948 [ERROR] django.request: [35;1m[35;1mInternal Server Error: /handler/image-upload[0m[0m
Traceback (most recent call last):
  File "/Users/chaelee/PycharmProjects/syu_capstone_2022_1_2/BloomingMind/Handler/views.py", line 48, in post
    image_save(image_file)
  File "/Users/chaelee/PycharmProjects/syu_capstone_2022_1_2/BloomingMind/Handler/views.py", line 91, in image_save
    image_file = is_image_file(image_file)
  File "/Users/chaelee/PycharmProjects/syu_capstone_2022_1_2/BloomingMind/Handler/views.py", line 80, in is_image_file
    _, extension = os.path.splitext(filename)
  File "/Users/chaelee/anaconda3/envs/syu_capstone_2022_1_2/lib/python3.9/posixpath.py", line 118, in splitext
    p = os.fspath(p)
TypeError: expected str, bytes or os.PathLike object, not InMemoryUploadedFile

During handling of the above exception, another exception occurred:

Traceback (most recent call last):
  File "/Users/chaelee/anaconda3/envs/syu_capstone_2022_1_2/lib/python3.9/site-packages/asgiref/sync.py", line 486, in thread_handler
    raise exc_info[1]
  File "/Users/chaelee/anaconda3/envs/syu_capstone_2022_1_2/lib/python3.9/site-packages/django/core/handlers/exception.py", line 42, in inner
    response = await get_response(request)
  File "/Users/chaelee/anaconda3/envs/syu_capstone_2022_1_2/lib/python3.9/site-packages/django/core/handlers/base.py", line 253, in _get_response_async
    response = await wrapped_callback(
  File "/Users/chaelee/anaconda3/envs/syu_capstone_2022_1_2/lib/python3.9/site-packages/asgiref/sync.py", line 448, in __call__
    ret = await asyncio.wait_for(future, timeout=None)
  File "/Users/chaelee/anaconda3/envs/syu_capstone_2022_1_2/lib/python3.9/asyncio/tasks.py", line 442, in wait_for
    return await fut
  File "/Users/chaelee/anaconda3/envs/syu_capstone_2022_1_2/lib/python3.9/site-packages/asgiref/current_thread_executor.py", line 22, in run
    result = self.fn(*self.args, **self.kwargs)
  File "/Users/chaelee/anaconda3/envs/syu_capstone_2022_1_2/lib/python3.9/site-packages/asgiref/sync.py", line 490, in thread_handler
    return func(*args, **kwargs)
  File "/Users/chaelee/anaconda3/envs/syu_capstone_2022_1_2/lib/python3.9/site-packages/django/views/generic/base.py", line 104, in view
    return self.dispatch(request, *args, **kwargs)
  File "/Users/chaelee/anaconda3/envs/syu_capstone_2022_1_2/lib/python3.9/site-packages/django/views/generic/base.py", line 143, in dispatch
    return handler(request, *args, **kwargs)
  File "/Users/chaelee/anaconda3/envs/syu_capstone_2022_1_2/lib/python3.9/site-packages/django/views/decorators/csrf.py", line 56, in wrapper_view
    return view_func(*args, **kwargs)
  File "/Users/chaelee/PycharmProjects/syu_capstone_2022_1_2/BloomingMind/Handler/views.py", line 62, in post
    return JsonResponse(
  File "/Users/chaelee/anaconda3/envs/syu_capstone_2022_1_2/lib/python3.9/site-packages/django/http/response.py", line 748, in __init__
    data = json.dumps(data, cls=encoder, **json_dumps_params)
  File "/Users/chaelee/anaconda3/envs/syu_capstone_2022_1_2/lib/python3.9/json/__init__.py", line 234, in dumps
    return cls(
  File "/Users/chaelee/anaconda3/envs/syu_capstone_2022_1_2/lib/python3.9/json/encoder.py", line 199, in encode
    chunks = self.iterencode(o, _one_shot=True)
  File "/Users/chaelee/anaconda3/envs/syu_capstone_2022_1_2/lib/python3.9/json/encoder.py", line 257, in iterencode
    return _iterencode(o, 0)
  File "/Users/chaelee/anaconda3/envs/syu_capstone_2022_1_2/lib/python3.9/site-packages/django/core/serializers/json.py", line 106, in default
    return super().default(o)
  File "/Users/chaelee/anaconda3/envs/syu_capstone_2022_1_2/lib/python3.9/json/encoder.py", line 179, in default
    raise TypeError(f'Object of type {o.__class__.__name__} '
TypeError: Object of type set is not JSON serializable


25/May/2023 21:06:47,069 [ERROR] django.request: [35;1m[35;1mInternal Server Error: /handler/image-upload[0m[0m
Traceback (most recent call last):
  File "/Users/chaelee/PycharmProjects/syu_capstone_2022_1_2/BloomingMind/Handler/views.py", line 48, in post
    image_save(image_file)
  File "/Users/chaelee/PycharmProjects/syu_capstone_2022_1_2/BloomingMind/Handler/views.py", line 91, in image_save
    image_file = is_image_file(image_file)
  File "/Users/chaelee/PycharmProjects/syu_capstone_2022_1_2/BloomingMind/Handler/views.py", line 80, in is_image_file
    _, extension = os.path.splitext(filename)
  File "/Users/chaelee/anaconda3/envs/syu_capstone_2022_1_2/lib/python3.9/posixpath.py", line 118, in splitext
    p = os.fspath(p)
TypeError: expected str, bytes or os.PathLike object, not InMemoryUploadedFile

During handling of the above exception, another exception occurred:

Traceback (most recent call last):
  File "/Users/chaelee/anaconda3/envs/syu_capstone_2022_1_2/lib/python3.9/site-packages/asgiref/sync.py", line 486, in thread_handler
    raise exc_info[1]
  File "/Users/chaelee/anaconda3/envs/syu_capstone_2022_1_2/lib/python3.9/site-packages/django/core/handlers/exception.py", line 42, in inner
    response = await get_response(request)
  File "/Users/chaelee/anaconda3/envs/syu_capstone_2022_1_2/lib/python3.9/site-packages/django/core/handlers/base.py", line 253, in _get_response_async
    response = await wrapped_callback(
  File "/Users/chaelee/anaconda3/envs/syu_capstone_2022_1_2/lib/python3.9/site-packages/asgiref/sync.py", line 448, in __call__
    ret = await asyncio.wait_for(future, timeout=None)
  File "/Users/chaelee/anaconda3/envs/syu_capstone_2022_1_2/lib/python3.9/asyncio/tasks.py", line 442, in wait_for
    return await fut
  File "/Users/chaelee/anaconda3/envs/syu_capstone_2022_1_2/lib/python3.9/site-packages/asgiref/current_thread_executor.py", line 22, in run
    result = self.fn(*self.args, **self.kwargs)
  File "/Users/chaelee/anaconda3/envs/syu_capstone_2022_1_2/lib/python3.9/site-packages/asgiref/sync.py", line 490, in thread_handler
    return func(*args, **kwargs)
  File "/Users/chaelee/anaconda3/envs/syu_capstone_2022_1_2/lib/python3.9/site-packages/django/views/generic/base.py", line 104, in view
    return self.dispatch(request, *args, **kwargs)
  File "/Users/chaelee/anaconda3/envs/syu_capstone_2022_1_2/lib/python3.9/site-packages/django/views/generic/base.py", line 143, in dispatch
    return handler(request, *args, **kwargs)
  File "/Users/chaelee/anaconda3/envs/syu_capstone_2022_1_2/lib/python3.9/site-packages/django/views/decorators/csrf.py", line 56, in wrapper_view
    return view_func(*args, **kwargs)
  File "/Users/chaelee/PycharmProjects/syu_capstone_2022_1_2/BloomingMind/Handler/views.py", line 62, in post
    return JsonResponse(
  File "/Users/chaelee/anaconda3/envs/syu_capstone_2022_1_2/lib/python3.9/site-packages/django/http/response.py", line 748, in __init__
    data = json.dumps(data, cls=encoder, **json_dumps_params)
  File "/Users/chaelee/anaconda3/envs/syu_capstone_2022_1_2/lib/python3.9/json/__init__.py", line 234, in dumps
    return cls(
  File "/Users/chaelee/anaconda3/envs/syu_capstone_2022_1_2/lib/python3.9/json/encoder.py", line 199, in encode
    chunks = self.iterencode(o, _one_shot=True)
  File "/Users/chaelee/anaconda3/envs/syu_capstone_2022_1_2/lib/python3.9/json/encoder.py", line 257, in iterencode
    return _iterencode(o, 0)
  File "/Users/chaelee/anaconda3/envs/syu_capstone_2022_1_2/lib/python3.9/site-packages/django/core/serializers/json.py", line 106, in default
    return super().default(o)
  File "/Users/chaelee/anaconda3/envs/syu_capstone_2022_1_2/lib/python3.9/json/encoder.py", line 179, in default
    raise TypeError(f'Object of type {o.__class__.__name__} '
TypeError: Object of type set is not JSON serializable


25/May/2023 21:07:35,269 [ERROR] django.request: [35;1m[35;1mInternal Server Error: /handler/image-upload[0m[0m
Traceback (most recent call last):
  File "/Users/chaelee/PycharmProjects/syu_capstone_2022_1_2/BloomingMind/Handler/views.py", line 48, in post
    image_save(image_file)
  File "/Users/chaelee/PycharmProjects/syu_capstone_2022_1_2/BloomingMind/Handler/views.py", line 91, in image_save
    image_file = is_image_file(image_file)
  File "/Users/chaelee/PycharmProjects/syu_capstone_2022_1_2/BloomingMind/Handler/views.py", line 80, in is_image_file
    _, extension = os.path.splitext(filename)
  File "/Users/chaelee/anaconda3/envs/syu_capstone_2022_1_2/lib/python3.9/posixpath.py", line 118, in splitext
    p = os.fspath(p)
TypeError: expected str, bytes or os.PathLike object, not InMemoryUploadedFile

During handling of the above exception, another exception occurred:

Traceback (most recent call last):
  File "/Users/chaelee/anaconda3/envs/syu_capstone_2022_1_2/lib/python3.9/site-packages/asgiref/sync.py", line 486, in thread_handler
    raise exc_info[1]
  File "/Users/chaelee/anaconda3/envs/syu_capstone_2022_1_2/lib/python3.9/site-packages/django/core/handlers/exception.py", line 42, in inner
    response = await get_response(request)
  File "/Users/chaelee/anaconda3/envs/syu_capstone_2022_1_2/lib/python3.9/site-packages/django/core/handlers/base.py", line 253, in _get_response_async
    response = await wrapped_callback(
  File "/Users/chaelee/anaconda3/envs/syu_capstone_2022_1_2/lib/python3.9/site-packages/asgiref/sync.py", line 448, in __call__
    ret = await asyncio.wait_for(future, timeout=None)
  File "/Users/chaelee/anaconda3/envs/syu_capstone_2022_1_2/lib/python3.9/asyncio/tasks.py", line 442, in wait_for
    return await fut
  File "/Users/chaelee/anaconda3/envs/syu_capstone_2022_1_2/lib/python3.9/site-packages/asgiref/current_thread_executor.py", line 22, in run
    result = self.fn(*self.args, **self.kwargs)
  File "/Users/chaelee/anaconda3/envs/syu_capstone_2022_1_2/lib/python3.9/site-packages/asgiref/sync.py", line 490, in thread_handler
    return func(*args, **kwargs)
  File "/Users/chaelee/anaconda3/envs/syu_capstone_2022_1_2/lib/python3.9/site-packages/django/views/generic/base.py", line 104, in view
    return self.dispatch(request, *args, **kwargs)
  File "/Users/chaelee/anaconda3/envs/syu_capstone_2022_1_2/lib/python3.9/site-packages/django/views/generic/base.py", line 143, in dispatch
    return handler(request, *args, **kwargs)
  File "/Users/chaelee/anaconda3/envs/syu_capstone_2022_1_2/lib/python3.9/site-packages/django/views/decorators/csrf.py", line 56, in wrapper_view
    return view_func(*args, **kwargs)
  File "/Users/chaelee/PycharmProjects/syu_capstone_2022_1_2/BloomingMind/Handler/views.py", line 62, in post
    return JsonResponse(
  File "/Users/chaelee/anaconda3/envs/syu_capstone_2022_1_2/lib/python3.9/site-packages/django/http/response.py", line 748, in __init__
    data = json.dumps(data, cls=encoder, **json_dumps_params)
  File "/Users/chaelee/anaconda3/envs/syu_capstone_2022_1_2/lib/python3.9/json/__init__.py", line 234, in dumps
    return cls(
  File "/Users/chaelee/anaconda3/envs/syu_capstone_2022_1_2/lib/python3.9/json/encoder.py", line 199, in encode
    chunks = self.iterencode(o, _one_shot=True)
  File "/Users/chaelee/anaconda3/envs/syu_capstone_2022_1_2/lib/python3.9/json/encoder.py", line 257, in iterencode
    return _iterencode(o, 0)
  File "/Users/chaelee/anaconda3/envs/syu_capstone_2022_1_2/lib/python3.9/site-packages/django/core/serializers/json.py", line 106, in default
    return super().default(o)
  File "/Users/chaelee/anaconda3/envs/syu_capstone_2022_1_2/lib/python3.9/json/encoder.py", line 179, in default
    raise TypeError(f'Object of type {o.__class__.__name__} '
TypeError: Object of type set is not JSON serializable


25/May/2023 21:08:21,103 [ERROR] django.request: [35;1m[35;1mInternal Server Error: /handler/image-upload[0m[0m
Traceback (most recent call last):
  File "/Users/chaelee/PycharmProjects/syu_capstone_2022_1_2/BloomingMind/Handler/views.py", line 48, in post
    image_save(image_file)
  File "/Users/chaelee/PycharmProjects/syu_capstone_2022_1_2/BloomingMind/Handler/views.py", line 92, in image_save
    image_file = is_image_file(image_file)
  File "/Users/chaelee/PycharmProjects/syu_capstone_2022_1_2/BloomingMind/Handler/views.py", line 80, in is_image_file
    _, extension = os.path.splitext(filename)
  File "/Users/chaelee/anaconda3/envs/syu_capstone_2022_1_2/lib/python3.9/posixpath.py", line 118, in splitext
    p = os.fspath(p)
TypeError: expected str, bytes or os.PathLike object, not InMemoryUploadedFile

During handling of the above exception, another exception occurred:

Traceback (most recent call last):
  File "/Users/chaelee/anaconda3/envs/syu_capstone_2022_1_2/lib/python3.9/site-packages/asgiref/sync.py", line 486, in thread_handler
    raise exc_info[1]
  File "/Users/chaelee/anaconda3/envs/syu_capstone_2022_1_2/lib/python3.9/site-packages/django/core/handlers/exception.py", line 42, in inner
    response = await get_response(request)
  File "/Users/chaelee/anaconda3/envs/syu_capstone_2022_1_2/lib/python3.9/site-packages/django/core/handlers/base.py", line 253, in _get_response_async
    response = await wrapped_callback(
  File "/Users/chaelee/anaconda3/envs/syu_capstone_2022_1_2/lib/python3.9/site-packages/asgiref/sync.py", line 448, in __call__
    ret = await asyncio.wait_for(future, timeout=None)
  File "/Users/chaelee/anaconda3/envs/syu_capstone_2022_1_2/lib/python3.9/asyncio/tasks.py", line 442, in wait_for
    return await fut
  File "/Users/chaelee/anaconda3/envs/syu_capstone_2022_1_2/lib/python3.9/site-packages/asgiref/current_thread_executor.py", line 22, in run
    result = self.fn(*self.args, **self.kwargs)
  File "/Users/chaelee/anaconda3/envs/syu_capstone_2022_1_2/lib/python3.9/site-packages/asgiref/sync.py", line 490, in thread_handler
    return func(*args, **kwargs)
  File "/Users/chaelee/anaconda3/envs/syu_capstone_2022_1_2/lib/python3.9/site-packages/django/views/generic/base.py", line 104, in view
    return self.dispatch(request, *args, **kwargs)
  File "/Users/chaelee/anaconda3/envs/syu_capstone_2022_1_2/lib/python3.9/site-packages/django/views/generic/base.py", line 143, in dispatch
    return handler(request, *args, **kwargs)
  File "/Users/chaelee/anaconda3/envs/syu_capstone_2022_1_2/lib/python3.9/site-packages/django/views/decorators/csrf.py", line 56, in wrapper_view
    return view_func(*args, **kwargs)
  File "/Users/chaelee/PycharmProjects/syu_capstone_2022_1_2/BloomingMind/Handler/views.py", line 62, in post
    return JsonResponse(
  File "/Users/chaelee/anaconda3/envs/syu_capstone_2022_1_2/lib/python3.9/site-packages/django/http/response.py", line 748, in __init__
    data = json.dumps(data, cls=encoder, **json_dumps_params)
  File "/Users/chaelee/anaconda3/envs/syu_capstone_2022_1_2/lib/python3.9/json/__init__.py", line 234, in dumps
    return cls(
  File "/Users/chaelee/anaconda3/envs/syu_capstone_2022_1_2/lib/python3.9/json/encoder.py", line 199, in encode
    chunks = self.iterencode(o, _one_shot=True)
  File "/Users/chaelee/anaconda3/envs/syu_capstone_2022_1_2/lib/python3.9/json/encoder.py", line 257, in iterencode
    return _iterencode(o, 0)
  File "/Users/chaelee/anaconda3/envs/syu_capstone_2022_1_2/lib/python3.9/site-packages/django/core/serializers/json.py", line 106, in default
    return super().default(o)
  File "/Users/chaelee/anaconda3/envs/syu_capstone_2022_1_2/lib/python3.9/json/encoder.py", line 179, in default
    raise TypeError(f'Object of type {o.__class__.__name__} '
TypeError: Object of type set is not JSON serializable


25/May/2023 21:08:55,035 [ERROR] django.request: [35;1m[35;1mInternal Server Error: /handler/image-upload[0m[0m
Traceback (most recent call last):
  File "/Users/chaelee/PycharmProjects/syu_capstone_2022_1_2/BloomingMind/Handler/views.py", line 48, in post
    image_save(image_file)
  File "/Users/chaelee/PycharmProjects/syu_capstone_2022_1_2/BloomingMind/Handler/views.py", line 93, in image_save
    image_file = is_image_file(image_file)
  File "/Users/chaelee/PycharmProjects/syu_capstone_2022_1_2/BloomingMind/Handler/views.py", line 80, in is_image_file
    print(os.path.splitext(filename))
  File "/Users/chaelee/anaconda3/envs/syu_capstone_2022_1_2/lib/python3.9/posixpath.py", line 118, in splitext
    p = os.fspath(p)
TypeError: expected str, bytes or os.PathLike object, not InMemoryUploadedFile

During handling of the above exception, another exception occurred:

Traceback (most recent call last):
  File "/Users/chaelee/anaconda3/envs/syu_capstone_2022_1_2/lib/python3.9/site-packages/asgiref/sync.py", line 486, in thread_handler
    raise exc_info[1]
  File "/Users/chaelee/anaconda3/envs/syu_capstone_2022_1_2/lib/python3.9/site-packages/django/core/handlers/exception.py", line 42, in inner
    response = await get_response(request)
  File "/Users/chaelee/anaconda3/envs/syu_capstone_2022_1_2/lib/python3.9/site-packages/django/core/handlers/base.py", line 253, in _get_response_async
    response = await wrapped_callback(
  File "/Users/chaelee/anaconda3/envs/syu_capstone_2022_1_2/lib/python3.9/site-packages/asgiref/sync.py", line 448, in __call__
    ret = await asyncio.wait_for(future, timeout=None)
  File "/Users/chaelee/anaconda3/envs/syu_capstone_2022_1_2/lib/python3.9/asyncio/tasks.py", line 442, in wait_for
    return await fut
  File "/Users/chaelee/anaconda3/envs/syu_capstone_2022_1_2/lib/python3.9/site-packages/asgiref/current_thread_executor.py", line 22, in run
    result = self.fn(*self.args, **self.kwargs)
  File "/Users/chaelee/anaconda3/envs/syu_capstone_2022_1_2/lib/python3.9/site-packages/asgiref/sync.py", line 490, in thread_handler
    return func(*args, **kwargs)
  File "/Users/chaelee/anaconda3/envs/syu_capstone_2022_1_2/lib/python3.9/site-packages/django/views/generic/base.py", line 104, in view
    return self.dispatch(request, *args, **kwargs)
  File "/Users/chaelee/anaconda3/envs/syu_capstone_2022_1_2/lib/python3.9/site-packages/django/views/generic/base.py", line 143, in dispatch
    return handler(request, *args, **kwargs)
  File "/Users/chaelee/anaconda3/envs/syu_capstone_2022_1_2/lib/python3.9/site-packages/django/views/decorators/csrf.py", line 56, in wrapper_view
    return view_func(*args, **kwargs)
  File "/Users/chaelee/PycharmProjects/syu_capstone_2022_1_2/BloomingMind/Handler/views.py", line 62, in post
    return JsonResponse(
  File "/Users/chaelee/anaconda3/envs/syu_capstone_2022_1_2/lib/python3.9/site-packages/django/http/response.py", line 748, in __init__
    data = json.dumps(data, cls=encoder, **json_dumps_params)
  File "/Users/chaelee/anaconda3/envs/syu_capstone_2022_1_2/lib/python3.9/json/__init__.py", line 234, in dumps
    return cls(
  File "/Users/chaelee/anaconda3/envs/syu_capstone_2022_1_2/lib/python3.9/json/encoder.py", line 199, in encode
    chunks = self.iterencode(o, _one_shot=True)
  File "/Users/chaelee/anaconda3/envs/syu_capstone_2022_1_2/lib/python3.9/json/encoder.py", line 257, in iterencode
    return _iterencode(o, 0)
  File "/Users/chaelee/anaconda3/envs/syu_capstone_2022_1_2/lib/python3.9/site-packages/django/core/serializers/json.py", line 106, in default
    return super().default(o)
  File "/Users/chaelee/anaconda3/envs/syu_capstone_2022_1_2/lib/python3.9/json/encoder.py", line 179, in default
    raise TypeError(f'Object of type {o.__class__.__name__} '
TypeError: Object of type set is not JSON serializable


25/May/2023 21:09:19,166 [ERROR] django.request: [35;1m[35;1mInternal Server Error: /handler/image-upload[0m[0m
Traceback (most recent call last):
  File "/Users/chaelee/PycharmProjects/syu_capstone_2022_1_2/BloomingMind/Handler/views.py", line 48, in post
    image_save(image_file)
  File "/Users/chaelee/PycharmProjects/syu_capstone_2022_1_2/BloomingMind/Handler/views.py", line 93, in image_save
    image_file = is_image_file(image_file)
  File "/Users/chaelee/PycharmProjects/syu_capstone_2022_1_2/BloomingMind/Handler/views.py", line 80, in is_image_file
    print(os.path.splitext(filename))
  File "/Users/chaelee/anaconda3/envs/syu_capstone_2022_1_2/lib/python3.9/posixpath.py", line 118, in splitext
    p = os.fspath(p)
TypeError: expected str, bytes or os.PathLike object, not InMemoryUploadedFile

During handling of the above exception, another exception occurred:

Traceback (most recent call last):
  File "/Users/chaelee/anaconda3/envs/syu_capstone_2022_1_2/lib/python3.9/site-packages/asgiref/sync.py", line 486, in thread_handler
    raise exc_info[1]
  File "/Users/chaelee/anaconda3/envs/syu_capstone_2022_1_2/lib/python3.9/site-packages/django/core/handlers/exception.py", line 42, in inner
    response = await get_response(request)
  File "/Users/chaelee/anaconda3/envs/syu_capstone_2022_1_2/lib/python3.9/site-packages/django/core/handlers/base.py", line 253, in _get_response_async
    response = await wrapped_callback(
  File "/Users/chaelee/anaconda3/envs/syu_capstone_2022_1_2/lib/python3.9/site-packages/asgiref/sync.py", line 448, in __call__
    ret = await asyncio.wait_for(future, timeout=None)
  File "/Users/chaelee/anaconda3/envs/syu_capstone_2022_1_2/lib/python3.9/asyncio/tasks.py", line 442, in wait_for
    return await fut
  File "/Users/chaelee/anaconda3/envs/syu_capstone_2022_1_2/lib/python3.9/site-packages/asgiref/current_thread_executor.py", line 22, in run
    result = self.fn(*self.args, **self.kwargs)
  File "/Users/chaelee/anaconda3/envs/syu_capstone_2022_1_2/lib/python3.9/site-packages/asgiref/sync.py", line 490, in thread_handler
    return func(*args, **kwargs)
  File "/Users/chaelee/anaconda3/envs/syu_capstone_2022_1_2/lib/python3.9/site-packages/django/views/generic/base.py", line 104, in view
    return self.dispatch(request, *args, **kwargs)
  File "/Users/chaelee/anaconda3/envs/syu_capstone_2022_1_2/lib/python3.9/site-packages/django/views/generic/base.py", line 143, in dispatch
    return handler(request, *args, **kwargs)
  File "/Users/chaelee/anaconda3/envs/syu_capstone_2022_1_2/lib/python3.9/site-packages/django/views/decorators/csrf.py", line 56, in wrapper_view
    return view_func(*args, **kwargs)
  File "/Users/chaelee/PycharmProjects/syu_capstone_2022_1_2/BloomingMind/Handler/views.py", line 62, in post
    return JsonResponse(
  File "/Users/chaelee/anaconda3/envs/syu_capstone_2022_1_2/lib/python3.9/site-packages/django/http/response.py", line 748, in __init__
    data = json.dumps(data, cls=encoder, **json_dumps_params)
  File "/Users/chaelee/anaconda3/envs/syu_capstone_2022_1_2/lib/python3.9/json/__init__.py", line 234, in dumps
    return cls(
  File "/Users/chaelee/anaconda3/envs/syu_capstone_2022_1_2/lib/python3.9/json/encoder.py", line 199, in encode
    chunks = self.iterencode(o, _one_shot=True)
  File "/Users/chaelee/anaconda3/envs/syu_capstone_2022_1_2/lib/python3.9/json/encoder.py", line 257, in iterencode
    return _iterencode(o, 0)
  File "/Users/chaelee/anaconda3/envs/syu_capstone_2022_1_2/lib/python3.9/site-packages/django/core/serializers/json.py", line 106, in default
    return super().default(o)
  File "/Users/chaelee/anaconda3/envs/syu_capstone_2022_1_2/lib/python3.9/json/encoder.py", line 179, in default
    raise TypeError(f'Object of type {o.__class__.__name__} '
TypeError: Object of type set is not JSON serializable


25/May/2023 21:09:47,260 [ERROR] django.request: [35;1m[35;1mInternal Server Error: /handler/image-upload[0m[0m
Traceback (most recent call last):
  File "/Users/chaelee/PycharmProjects/syu_capstone_2022_1_2/BloomingMind/Handler/views.py", line 48, in post
    image_save(image_file)
  File "/Users/chaelee/PycharmProjects/syu_capstone_2022_1_2/BloomingMind/Handler/views.py", line 93, in image_save
    image_file = is_image_file(image_file)
  File "/Users/chaelee/PycharmProjects/syu_capstone_2022_1_2/BloomingMind/Handler/views.py", line 81, in is_image_file
    _, extension = os.path.splitext(filename)
  File "/Users/chaelee/anaconda3/envs/syu_capstone_2022_1_2/lib/python3.9/posixpath.py", line 118, in splitext
    p = os.fspath(p)
TypeError: expected str, bytes or os.PathLike object, not InMemoryUploadedFile

During handling of the above exception, another exception occurred:

Traceback (most recent call last):
  File "/Users/chaelee/anaconda3/envs/syu_capstone_2022_1_2/lib/python3.9/site-packages/asgiref/sync.py", line 486, in thread_handler
    raise exc_info[1]
  File "/Users/chaelee/anaconda3/envs/syu_capstone_2022_1_2/lib/python3.9/site-packages/django/core/handlers/exception.py", line 42, in inner
    response = await get_response(request)
  File "/Users/chaelee/anaconda3/envs/syu_capstone_2022_1_2/lib/python3.9/site-packages/django/core/handlers/base.py", line 253, in _get_response_async
    response = await wrapped_callback(
  File "/Users/chaelee/anaconda3/envs/syu_capstone_2022_1_2/lib/python3.9/site-packages/asgiref/sync.py", line 448, in __call__
    ret = await asyncio.wait_for(future, timeout=None)
  File "/Users/chaelee/anaconda3/envs/syu_capstone_2022_1_2/lib/python3.9/asyncio/tasks.py", line 442, in wait_for
    return await fut
  File "/Users/chaelee/anaconda3/envs/syu_capstone_2022_1_2/lib/python3.9/site-packages/asgiref/current_thread_executor.py", line 22, in run
    result = self.fn(*self.args, **self.kwargs)
  File "/Users/chaelee/anaconda3/envs/syu_capstone_2022_1_2/lib/python3.9/site-packages/asgiref/sync.py", line 490, in thread_handler
    return func(*args, **kwargs)
  File "/Users/chaelee/anaconda3/envs/syu_capstone_2022_1_2/lib/python3.9/site-packages/django/views/generic/base.py", line 104, in view
    return self.dispatch(request, *args, **kwargs)
  File "/Users/chaelee/anaconda3/envs/syu_capstone_2022_1_2/lib/python3.9/site-packages/django/views/generic/base.py", line 143, in dispatch
    return handler(request, *args, **kwargs)
  File "/Users/chaelee/anaconda3/envs/syu_capstone_2022_1_2/lib/python3.9/site-packages/django/views/decorators/csrf.py", line 56, in wrapper_view
    return view_func(*args, **kwargs)
  File "/Users/chaelee/PycharmProjects/syu_capstone_2022_1_2/BloomingMind/Handler/views.py", line 62, in post
    return JsonResponse(
  File "/Users/chaelee/anaconda3/envs/syu_capstone_2022_1_2/lib/python3.9/site-packages/django/http/response.py", line 748, in __init__
    data = json.dumps(data, cls=encoder, **json_dumps_params)
  File "/Users/chaelee/anaconda3/envs/syu_capstone_2022_1_2/lib/python3.9/json/__init__.py", line 234, in dumps
    return cls(
  File "/Users/chaelee/anaconda3/envs/syu_capstone_2022_1_2/lib/python3.9/json/encoder.py", line 199, in encode
    chunks = self.iterencode(o, _one_shot=True)
  File "/Users/chaelee/anaconda3/envs/syu_capstone_2022_1_2/lib/python3.9/json/encoder.py", line 257, in iterencode
    return _iterencode(o, 0)
  File "/Users/chaelee/anaconda3/envs/syu_capstone_2022_1_2/lib/python3.9/site-packages/django/core/serializers/json.py", line 106, in default
    return super().default(o)
  File "/Users/chaelee/anaconda3/envs/syu_capstone_2022_1_2/lib/python3.9/json/encoder.py", line 179, in default
    raise TypeError(f'Object of type {o.__class__.__name__} '
TypeError: Object of type set is not JSON serializable


25/May/2023 21:11:06,670 [ERROR] django.request: [35;1m[35;1mInternal Server Error: /handler/image-upload[0m[0m
Traceback (most recent call last):
  File "/Users/chaelee/PycharmProjects/syu_capstone_2022_1_2/BloomingMind/Handler/views.py", line 48, in post
    image_save(image_file)
  File "/Users/chaelee/PycharmProjects/syu_capstone_2022_1_2/BloomingMind/Handler/views.py", line 93, in image_save
    image_file = is_image_file(image_file)
  File "/Users/chaelee/PycharmProjects/syu_capstone_2022_1_2/BloomingMind/Handler/views.py", line 80, in is_image_file
    print(os.path.splitext(str(filename.filename)))
AttributeError: 'InMemoryUploadedFile' object has no attribute 'filename'

During handling of the above exception, another exception occurred:

Traceback (most recent call last):
  File "/Users/chaelee/anaconda3/envs/syu_capstone_2022_1_2/lib/python3.9/site-packages/asgiref/sync.py", line 486, in thread_handler
    raise exc_info[1]
  File "/Users/chaelee/anaconda3/envs/syu_capstone_2022_1_2/lib/python3.9/site-packages/django/core/handlers/exception.py", line 42, in inner
    response = await get_response(request)
  File "/Users/chaelee/anaconda3/envs/syu_capstone_2022_1_2/lib/python3.9/site-packages/django/core/handlers/base.py", line 253, in _get_response_async
    response = await wrapped_callback(
  File "/Users/chaelee/anaconda3/envs/syu_capstone_2022_1_2/lib/python3.9/site-packages/asgiref/sync.py", line 448, in __call__
    ret = await asyncio.wait_for(future, timeout=None)
  File "/Users/chaelee/anaconda3/envs/syu_capstone_2022_1_2/lib/python3.9/asyncio/tasks.py", line 442, in wait_for
    return await fut
  File "/Users/chaelee/anaconda3/envs/syu_capstone_2022_1_2/lib/python3.9/site-packages/asgiref/current_thread_executor.py", line 22, in run
    result = self.fn(*self.args, **self.kwargs)
  File "/Users/chaelee/anaconda3/envs/syu_capstone_2022_1_2/lib/python3.9/site-packages/asgiref/sync.py", line 490, in thread_handler
    return func(*args, **kwargs)
  File "/Users/chaelee/anaconda3/envs/syu_capstone_2022_1_2/lib/python3.9/site-packages/django/views/generic/base.py", line 104, in view
    return self.dispatch(request, *args, **kwargs)
  File "/Users/chaelee/anaconda3/envs/syu_capstone_2022_1_2/lib/python3.9/site-packages/django/views/generic/base.py", line 143, in dispatch
    return handler(request, *args, **kwargs)
  File "/Users/chaelee/anaconda3/envs/syu_capstone_2022_1_2/lib/python3.9/site-packages/django/views/decorators/csrf.py", line 56, in wrapper_view
    return view_func(*args, **kwargs)
  File "/Users/chaelee/PycharmProjects/syu_capstone_2022_1_2/BloomingMind/Handler/views.py", line 62, in post
    return JsonResponse(
  File "/Users/chaelee/anaconda3/envs/syu_capstone_2022_1_2/lib/python3.9/site-packages/django/http/response.py", line 748, in __init__
    data = json.dumps(data, cls=encoder, **json_dumps_params)
  File "/Users/chaelee/anaconda3/envs/syu_capstone_2022_1_2/lib/python3.9/json/__init__.py", line 234, in dumps
    return cls(
  File "/Users/chaelee/anaconda3/envs/syu_capstone_2022_1_2/lib/python3.9/json/encoder.py", line 199, in encode
    chunks = self.iterencode(o, _one_shot=True)
  File "/Users/chaelee/anaconda3/envs/syu_capstone_2022_1_2/lib/python3.9/json/encoder.py", line 257, in iterencode
    return _iterencode(o, 0)
  File "/Users/chaelee/anaconda3/envs/syu_capstone_2022_1_2/lib/python3.9/site-packages/django/core/serializers/json.py", line 106, in default
    return super().default(o)
  File "/Users/chaelee/anaconda3/envs/syu_capstone_2022_1_2/lib/python3.9/json/encoder.py", line 179, in default
    raise TypeError(f'Object of type {o.__class__.__name__} '
TypeError: Object of type set is not JSON serializable


25/May/2023 21:11:30,949 [ERROR] django.request: [35;1m[35;1mInternal Server Error: /handler/image-upload[0m[0m
Traceback (most recent call last):
  File "/Users/chaelee/PycharmProjects/syu_capstone_2022_1_2/BloomingMind/Handler/views.py", line 48, in post
    image_save(image_file)
  File "/Users/chaelee/PycharmProjects/syu_capstone_2022_1_2/BloomingMind/Handler/views.py", line 94, in image_save
    image_file = is_image_file(image_file)
  File "/Users/chaelee/PycharmProjects/syu_capstone_2022_1_2/BloomingMind/Handler/views.py", line 80, in is_image_file
    print(filename.filename)
AttributeError: 'InMemoryUploadedFile' object has no attribute 'filename'

During handling of the above exception, another exception occurred:

Traceback (most recent call last):
  File "/Users/chaelee/anaconda3/envs/syu_capstone_2022_1_2/lib/python3.9/site-packages/asgiref/sync.py", line 486, in thread_handler
    raise exc_info[1]
  File "/Users/chaelee/anaconda3/envs/syu_capstone_2022_1_2/lib/python3.9/site-packages/django/core/handlers/exception.py", line 42, in inner
    response = await get_response(request)
  File "/Users/chaelee/anaconda3/envs/syu_capstone_2022_1_2/lib/python3.9/site-packages/django/core/handlers/base.py", line 253, in _get_response_async
    response = await wrapped_callback(
  File "/Users/chaelee/anaconda3/envs/syu_capstone_2022_1_2/lib/python3.9/site-packages/asgiref/sync.py", line 448, in __call__
    ret = await asyncio.wait_for(future, timeout=None)
  File "/Users/chaelee/anaconda3/envs/syu_capstone_2022_1_2/lib/python3.9/asyncio/tasks.py", line 442, in wait_for
    return await fut
  File "/Users/chaelee/anaconda3/envs/syu_capstone_2022_1_2/lib/python3.9/site-packages/asgiref/current_thread_executor.py", line 22, in run
    result = self.fn(*self.args, **self.kwargs)
  File "/Users/chaelee/anaconda3/envs/syu_capstone_2022_1_2/lib/python3.9/site-packages/asgiref/sync.py", line 490, in thread_handler
    return func(*args, **kwargs)
  File "/Users/chaelee/anaconda3/envs/syu_capstone_2022_1_2/lib/python3.9/site-packages/django/views/generic/base.py", line 104, in view
    return self.dispatch(request, *args, **kwargs)
  File "/Users/chaelee/anaconda3/envs/syu_capstone_2022_1_2/lib/python3.9/site-packages/django/views/generic/base.py", line 143, in dispatch
    return handler(request, *args, **kwargs)
  File "/Users/chaelee/anaconda3/envs/syu_capstone_2022_1_2/lib/python3.9/site-packages/django/views/decorators/csrf.py", line 56, in wrapper_view
    return view_func(*args, **kwargs)
  File "/Users/chaelee/PycharmProjects/syu_capstone_2022_1_2/BloomingMind/Handler/views.py", line 62, in post
    return JsonResponse(
  File "/Users/chaelee/anaconda3/envs/syu_capstone_2022_1_2/lib/python3.9/site-packages/django/http/response.py", line 748, in __init__
    data = json.dumps(data, cls=encoder, **json_dumps_params)
  File "/Users/chaelee/anaconda3/envs/syu_capstone_2022_1_2/lib/python3.9/json/__init__.py", line 234, in dumps
    return cls(
  File "/Users/chaelee/anaconda3/envs/syu_capstone_2022_1_2/lib/python3.9/json/encoder.py", line 199, in encode
    chunks = self.iterencode(o, _one_shot=True)
  File "/Users/chaelee/anaconda3/envs/syu_capstone_2022_1_2/lib/python3.9/json/encoder.py", line 257, in iterencode
    return _iterencode(o, 0)
  File "/Users/chaelee/anaconda3/envs/syu_capstone_2022_1_2/lib/python3.9/site-packages/django/core/serializers/json.py", line 106, in default
    return super().default(o)
  File "/Users/chaelee/anaconda3/envs/syu_capstone_2022_1_2/lib/python3.9/json/encoder.py", line 179, in default
    raise TypeError(f'Object of type {o.__class__.__name__} '
TypeError: Object of type set is not JSON serializable


25/May/2023 21:11:49,453 [ERROR] django.request: [35;1m[35;1mInternal Server Error: /handler/image-upload[0m[0m
Traceback (most recent call last):
  File "/Users/chaelee/PycharmProjects/syu_capstone_2022_1_2/BloomingMind/Handler/views.py", line 48, in post
    image_save(image_file)
  File "/Users/chaelee/PycharmProjects/syu_capstone_2022_1_2/BloomingMind/Handler/views.py", line 94, in image_save
    image_file = is_image_file(image_file)
  File "/Users/chaelee/PycharmProjects/syu_capstone_2022_1_2/BloomingMind/Handler/views.py", line 80, in is_image_file
    print(filename.filename())
AttributeError: 'InMemoryUploadedFile' object has no attribute 'filename'

During handling of the above exception, another exception occurred:

Traceback (most recent call last):
  File "/Users/chaelee/anaconda3/envs/syu_capstone_2022_1_2/lib/python3.9/site-packages/asgiref/sync.py", line 486, in thread_handler
    raise exc_info[1]
  File "/Users/chaelee/anaconda3/envs/syu_capstone_2022_1_2/lib/python3.9/site-packages/django/core/handlers/exception.py", line 42, in inner
    response = await get_response(request)
  File "/Users/chaelee/anaconda3/envs/syu_capstone_2022_1_2/lib/python3.9/site-packages/django/core/handlers/base.py", line 253, in _get_response_async
    response = await wrapped_callback(
  File "/Users/chaelee/anaconda3/envs/syu_capstone_2022_1_2/lib/python3.9/site-packages/asgiref/sync.py", line 448, in __call__
    ret = await asyncio.wait_for(future, timeout=None)
  File "/Users/chaelee/anaconda3/envs/syu_capstone_2022_1_2/lib/python3.9/asyncio/tasks.py", line 442, in wait_for
    return await fut
  File "/Users/chaelee/anaconda3/envs/syu_capstone_2022_1_2/lib/python3.9/site-packages/asgiref/current_thread_executor.py", line 22, in run
    result = self.fn(*self.args, **self.kwargs)
  File "/Users/chaelee/anaconda3/envs/syu_capstone_2022_1_2/lib/python3.9/site-packages/asgiref/sync.py", line 490, in thread_handler
    return func(*args, **kwargs)
  File "/Users/chaelee/anaconda3/envs/syu_capstone_2022_1_2/lib/python3.9/site-packages/django/views/generic/base.py", line 104, in view
    return self.dispatch(request, *args, **kwargs)
  File "/Users/chaelee/anaconda3/envs/syu_capstone_2022_1_2/lib/python3.9/site-packages/django/views/generic/base.py", line 143, in dispatch
    return handler(request, *args, **kwargs)
  File "/Users/chaelee/anaconda3/envs/syu_capstone_2022_1_2/lib/python3.9/site-packages/django/views/decorators/csrf.py", line 56, in wrapper_view
    return view_func(*args, **kwargs)
  File "/Users/chaelee/PycharmProjects/syu_capstone_2022_1_2/BloomingMind/Handler/views.py", line 62, in post
    return JsonResponse(
  File "/Users/chaelee/anaconda3/envs/syu_capstone_2022_1_2/lib/python3.9/site-packages/django/http/response.py", line 748, in __init__
    data = json.dumps(data, cls=encoder, **json_dumps_params)
  File "/Users/chaelee/anaconda3/envs/syu_capstone_2022_1_2/lib/python3.9/json/__init__.py", line 234, in dumps
    return cls(
  File "/Users/chaelee/anaconda3/envs/syu_capstone_2022_1_2/lib/python3.9/json/encoder.py", line 199, in encode
    chunks = self.iterencode(o, _one_shot=True)
  File "/Users/chaelee/anaconda3/envs/syu_capstone_2022_1_2/lib/python3.9/json/encoder.py", line 257, in iterencode
    return _iterencode(o, 0)
  File "/Users/chaelee/anaconda3/envs/syu_capstone_2022_1_2/lib/python3.9/site-packages/django/core/serializers/json.py", line 106, in default
    return super().default(o)
  File "/Users/chaelee/anaconda3/envs/syu_capstone_2022_1_2/lib/python3.9/json/encoder.py", line 179, in default
    raise TypeError(f'Object of type {o.__class__.__name__} '
TypeError: Object of type set is not JSON serializable


25/May/2023 21:14:14,904 [ERROR] django.request: [35;1m[35;1mInternal Server Error: /handler/image-upload[0m[0m
Traceback (most recent call last):
  File "/Users/chaelee/PycharmProjects/syu_capstone_2022_1_2/BloomingMind/Handler/views.py", line 48, in post
    image_save(image_file)
  File "/Users/chaelee/PycharmProjects/syu_capstone_2022_1_2/BloomingMind/Handler/views.py", line 94, in image_save
    print(image_name+1)
TypeError: can only concatenate str (not "int") to str

During handling of the above exception, another exception occurred:

Traceback (most recent call last):
  File "/Users/chaelee/anaconda3/envs/syu_capstone_2022_1_2/lib/python3.9/site-packages/asgiref/sync.py", line 486, in thread_handler
    raise exc_info[1]
  File "/Users/chaelee/anaconda3/envs/syu_capstone_2022_1_2/lib/python3.9/site-packages/django/core/handlers/exception.py", line 42, in inner
    response = await get_response(request)
  File "/Users/chaelee/anaconda3/envs/syu_capstone_2022_1_2/lib/python3.9/site-packages/django/core/handlers/base.py", line 253, in _get_response_async
    response = await wrapped_callback(
  File "/Users/chaelee/anaconda3/envs/syu_capstone_2022_1_2/lib/python3.9/site-packages/asgiref/sync.py", line 448, in __call__
    ret = await asyncio.wait_for(future, timeout=None)
  File "/Users/chaelee/anaconda3/envs/syu_capstone_2022_1_2/lib/python3.9/asyncio/tasks.py", line 442, in wait_for
    return await fut
  File "/Users/chaelee/anaconda3/envs/syu_capstone_2022_1_2/lib/python3.9/site-packages/asgiref/current_thread_executor.py", line 22, in run
    result = self.fn(*self.args, **self.kwargs)
  File "/Users/chaelee/anaconda3/envs/syu_capstone_2022_1_2/lib/python3.9/site-packages/asgiref/sync.py", line 490, in thread_handler
    return func(*args, **kwargs)
  File "/Users/chaelee/anaconda3/envs/syu_capstone_2022_1_2/lib/python3.9/site-packages/django/views/generic/base.py", line 104, in view
    return self.dispatch(request, *args, **kwargs)
  File "/Users/chaelee/anaconda3/envs/syu_capstone_2022_1_2/lib/python3.9/site-packages/django/views/generic/base.py", line 143, in dispatch
    return handler(request, *args, **kwargs)
  File "/Users/chaelee/anaconda3/envs/syu_capstone_2022_1_2/lib/python3.9/site-packages/django/views/decorators/csrf.py", line 56, in wrapper_view
    return view_func(*args, **kwargs)
  File "/Users/chaelee/PycharmProjects/syu_capstone_2022_1_2/BloomingMind/Handler/views.py", line 62, in post
    return JsonResponse(
  File "/Users/chaelee/anaconda3/envs/syu_capstone_2022_1_2/lib/python3.9/site-packages/django/http/response.py", line 748, in __init__
    data = json.dumps(data, cls=encoder, **json_dumps_params)
  File "/Users/chaelee/anaconda3/envs/syu_capstone_2022_1_2/lib/python3.9/json/__init__.py", line 234, in dumps
    return cls(
  File "/Users/chaelee/anaconda3/envs/syu_capstone_2022_1_2/lib/python3.9/json/encoder.py", line 199, in encode
    chunks = self.iterencode(o, _one_shot=True)
  File "/Users/chaelee/anaconda3/envs/syu_capstone_2022_1_2/lib/python3.9/json/encoder.py", line 257, in iterencode
    return _iterencode(o, 0)
  File "/Users/chaelee/anaconda3/envs/syu_capstone_2022_1_2/lib/python3.9/site-packages/django/core/serializers/json.py", line 106, in default
    return super().default(o)
  File "/Users/chaelee/anaconda3/envs/syu_capstone_2022_1_2/lib/python3.9/json/encoder.py", line 179, in default
    raise TypeError(f'Object of type {o.__class__.__name__} '
TypeError: Object of type set is not JSON serializable


25/May/2023 21:14:26,277 [ERROR] django.request: [35;1m[35;1mInternal Server Error: /handler/image-upload[0m[0m
Traceback (most recent call last):
  File "/Users/chaelee/PycharmProjects/syu_capstone_2022_1_2/BloomingMind/Handler/views.py", line 48, in post
    image_save(image_file)
  File "/Users/chaelee/PycharmProjects/syu_capstone_2022_1_2/BloomingMind/Handler/views.py", line 97, in image_save
    image_file = is_image_file(image_file)
  File "/Users/chaelee/PycharmProjects/syu_capstone_2022_1_2/BloomingMind/Handler/views.py", line 80, in is_image_file
    print(filename.f)
AttributeError: 'InMemoryUploadedFile' object has no attribute 'f'

During handling of the above exception, another exception occurred:

Traceback (most recent call last):
  File "/Users/chaelee/anaconda3/envs/syu_capstone_2022_1_2/lib/python3.9/site-packages/asgiref/sync.py", line 486, in thread_handler
    raise exc_info[1]
  File "/Users/chaelee/anaconda3/envs/syu_capstone_2022_1_2/lib/python3.9/site-packages/django/core/handlers/exception.py", line 42, in inner
    response = await get_response(request)
  File "/Users/chaelee/anaconda3/envs/syu_capstone_2022_1_2/lib/python3.9/site-packages/django/core/handlers/base.py", line 253, in _get_response_async
    response = await wrapped_callback(
  File "/Users/chaelee/anaconda3/envs/syu_capstone_2022_1_2/lib/python3.9/site-packages/asgiref/sync.py", line 448, in __call__
    ret = await asyncio.wait_for(future, timeout=None)
  File "/Users/chaelee/anaconda3/envs/syu_capstone_2022_1_2/lib/python3.9/asyncio/tasks.py", line 442, in wait_for
    return await fut
  File "/Users/chaelee/anaconda3/envs/syu_capstone_2022_1_2/lib/python3.9/site-packages/asgiref/current_thread_executor.py", line 22, in run
    result = self.fn(*self.args, **self.kwargs)
  File "/Users/chaelee/anaconda3/envs/syu_capstone_2022_1_2/lib/python3.9/site-packages/asgiref/sync.py", line 490, in thread_handler
    return func(*args, **kwargs)
  File "/Users/chaelee/anaconda3/envs/syu_capstone_2022_1_2/lib/python3.9/site-packages/django/views/generic/base.py", line 104, in view
    return self.dispatch(request, *args, **kwargs)
  File "/Users/chaelee/anaconda3/envs/syu_capstone_2022_1_2/lib/python3.9/site-packages/django/views/generic/base.py", line 143, in dispatch
    return handler(request, *args, **kwargs)
  File "/Users/chaelee/anaconda3/envs/syu_capstone_2022_1_2/lib/python3.9/site-packages/django/views/decorators/csrf.py", line 56, in wrapper_view
    return view_func(*args, **kwargs)
  File "/Users/chaelee/PycharmProjects/syu_capstone_2022_1_2/BloomingMind/Handler/views.py", line 62, in post
    return JsonResponse(
  File "/Users/chaelee/anaconda3/envs/syu_capstone_2022_1_2/lib/python3.9/site-packages/django/http/response.py", line 748, in __init__
    data = json.dumps(data, cls=encoder, **json_dumps_params)
  File "/Users/chaelee/anaconda3/envs/syu_capstone_2022_1_2/lib/python3.9/json/__init__.py", line 234, in dumps
    return cls(
  File "/Users/chaelee/anaconda3/envs/syu_capstone_2022_1_2/lib/python3.9/json/encoder.py", line 199, in encode
    chunks = self.iterencode(o, _one_shot=True)
  File "/Users/chaelee/anaconda3/envs/syu_capstone_2022_1_2/lib/python3.9/json/encoder.py", line 257, in iterencode
    return _iterencode(o, 0)
  File "/Users/chaelee/anaconda3/envs/syu_capstone_2022_1_2/lib/python3.9/site-packages/django/core/serializers/json.py", line 106, in default
    return super().default(o)
  File "/Users/chaelee/anaconda3/envs/syu_capstone_2022_1_2/lib/python3.9/json/encoder.py", line 179, in default
    raise TypeError(f'Object of type {o.__class__.__name__} '
TypeError: Object of type set is not JSON serializable


25/May/2023 21:15:59,865 [ERROR] django.request: [35;1m[35;1mInternal Server Error: /handler/image-upload[0m[0m
Traceback (most recent call last):
  File "/Users/chaelee/PycharmProjects/syu_capstone_2022_1_2/BloomingMind/Handler/views.py", line 100, in image_save
    f.write(upload_image)
NameError: name 'upload_image' is not defined

During handling of the above exception, another exception occurred:

Traceback (most recent call last):
  File "/Users/chaelee/PycharmProjects/syu_capstone_2022_1_2/BloomingMind/Handler/views.py", line 48, in post
    image_save(image_file=image_file)
  File "/Users/chaelee/PycharmProjects/syu_capstone_2022_1_2/BloomingMind/Handler/views.py", line 103, in image_save
    raise ImageFIleError('This file cannot be read.')
Handler.exceptions.ImageFIleError: This file cannot be read.

During handling of the above exception, another exception occurred:

Traceback (most recent call last):
  File "/Users/chaelee/anaconda3/envs/syu_capstone_2022_1_2/lib/python3.9/site-packages/asgiref/sync.py", line 486, in thread_handler
    raise exc_info[1]
  File "/Users/chaelee/anaconda3/envs/syu_capstone_2022_1_2/lib/python3.9/site-packages/django/core/handlers/exception.py", line 42, in inner
    response = await get_response(request)
  File "/Users/chaelee/anaconda3/envs/syu_capstone_2022_1_2/lib/python3.9/site-packages/django/core/handlers/base.py", line 253, in _get_response_async
    response = await wrapped_callback(
  File "/Users/chaelee/anaconda3/envs/syu_capstone_2022_1_2/lib/python3.9/site-packages/asgiref/sync.py", line 448, in __call__
    ret = await asyncio.wait_for(future, timeout=None)
  File "/Users/chaelee/anaconda3/envs/syu_capstone_2022_1_2/lib/python3.9/asyncio/tasks.py", line 442, in wait_for
    return await fut
  File "/Users/chaelee/anaconda3/envs/syu_capstone_2022_1_2/lib/python3.9/site-packages/asgiref/current_thread_executor.py", line 22, in run
    result = self.fn(*self.args, **self.kwargs)
  File "/Users/chaelee/anaconda3/envs/syu_capstone_2022_1_2/lib/python3.9/site-packages/asgiref/sync.py", line 490, in thread_handler
    return func(*args, **kwargs)
  File "/Users/chaelee/anaconda3/envs/syu_capstone_2022_1_2/lib/python3.9/site-packages/django/views/generic/base.py", line 104, in view
    return self.dispatch(request, *args, **kwargs)
  File "/Users/chaelee/anaconda3/envs/syu_capstone_2022_1_2/lib/python3.9/site-packages/django/views/generic/base.py", line 143, in dispatch
    return handler(request, *args, **kwargs)
  File "/Users/chaelee/anaconda3/envs/syu_capstone_2022_1_2/lib/python3.9/site-packages/django/views/decorators/csrf.py", line 56, in wrapper_view
    return view_func(*args, **kwargs)
  File "/Users/chaelee/PycharmProjects/syu_capstone_2022_1_2/BloomingMind/Handler/views.py", line 62, in post
    return JsonResponse(
  File "/Users/chaelee/anaconda3/envs/syu_capstone_2022_1_2/lib/python3.9/site-packages/django/http/response.py", line 748, in __init__
    data = json.dumps(data, cls=encoder, **json_dumps_params)
  File "/Users/chaelee/anaconda3/envs/syu_capstone_2022_1_2/lib/python3.9/json/__init__.py", line 234, in dumps
    return cls(
  File "/Users/chaelee/anaconda3/envs/syu_capstone_2022_1_2/lib/python3.9/json/encoder.py", line 199, in encode
    chunks = self.iterencode(o, _one_shot=True)
  File "/Users/chaelee/anaconda3/envs/syu_capstone_2022_1_2/lib/python3.9/json/encoder.py", line 257, in iterencode
    return _iterencode(o, 0)
  File "/Users/chaelee/anaconda3/envs/syu_capstone_2022_1_2/lib/python3.9/site-packages/django/core/serializers/json.py", line 106, in default
    return super().default(o)
  File "/Users/chaelee/anaconda3/envs/syu_capstone_2022_1_2/lib/python3.9/json/encoder.py", line 179, in default
    raise TypeError(f'Object of type {o.__class__.__name__} '
TypeError: Object of type set is not JSON serializable


25/May/2023 21:32:02,146 [ERROR] django.request: [35;1m[35;1mInternal Server Error: /handler/image-upload[0m[0m
Traceback (most recent call last):
  File "/Users/chaelee/PycharmProjects/syu_capstone_2022_1_2/BloomingMind/Handler/views.py", line 49, in post
    image_save(image_file=image_file)
  File "/Users/chaelee/PycharmProjects/syu_capstone_2022_1_2/BloomingMind/Handler/views.py", line 101, in image_save
    raise ImageFIleError('This file cannot be read.')
Handler.exceptions.ImageFIleError: This file cannot be read.

During handling of the above exception, another exception occurred:

Traceback (most recent call last):
  File "/Users/chaelee/anaconda3/envs/syu_capstone_2022_1_2/lib/python3.9/site-packages/asgiref/sync.py", line 486, in thread_handler
    raise exc_info[1]
  File "/Users/chaelee/anaconda3/envs/syu_capstone_2022_1_2/lib/python3.9/site-packages/django/core/handlers/exception.py", line 42, in inner
    response = await get_response(request)
  File "/Users/chaelee/anaconda3/envs/syu_capstone_2022_1_2/lib/python3.9/site-packages/django/core/handlers/base.py", line 253, in _get_response_async
    response = await wrapped_callback(
  File "/Users/chaelee/anaconda3/envs/syu_capstone_2022_1_2/lib/python3.9/site-packages/asgiref/sync.py", line 448, in __call__
    ret = await asyncio.wait_for(future, timeout=None)
  File "/Users/chaelee/anaconda3/envs/syu_capstone_2022_1_2/lib/python3.9/asyncio/tasks.py", line 442, in wait_for
    return await fut
  File "/Users/chaelee/anaconda3/envs/syu_capstone_2022_1_2/lib/python3.9/site-packages/asgiref/current_thread_executor.py", line 22, in run
    result = self.fn(*self.args, **self.kwargs)
  File "/Users/chaelee/anaconda3/envs/syu_capstone_2022_1_2/lib/python3.9/site-packages/asgiref/sync.py", line 490, in thread_handler
    return func(*args, **kwargs)
  File "/Users/chaelee/anaconda3/envs/syu_capstone_2022_1_2/lib/python3.9/site-packages/django/views/generic/base.py", line 104, in view
    return self.dispatch(request, *args, **kwargs)
  File "/Users/chaelee/anaconda3/envs/syu_capstone_2022_1_2/lib/python3.9/site-packages/django/views/generic/base.py", line 143, in dispatch
    return handler(request, *args, **kwargs)
  File "/Users/chaelee/anaconda3/envs/syu_capstone_2022_1_2/lib/python3.9/site-packages/django/views/decorators/csrf.py", line 56, in wrapper_view
    return view_func(*args, **kwargs)
  File "/Users/chaelee/PycharmProjects/syu_capstone_2022_1_2/BloomingMind/Handler/views.py", line 63, in post
    return JsonResponse(
  File "/Users/chaelee/anaconda3/envs/syu_capstone_2022_1_2/lib/python3.9/site-packages/django/http/response.py", line 748, in __init__
    data = json.dumps(data, cls=encoder, **json_dumps_params)
  File "/Users/chaelee/anaconda3/envs/syu_capstone_2022_1_2/lib/python3.9/json/__init__.py", line 234, in dumps
    return cls(
  File "/Users/chaelee/anaconda3/envs/syu_capstone_2022_1_2/lib/python3.9/json/encoder.py", line 199, in encode
    chunks = self.iterencode(o, _one_shot=True)
  File "/Users/chaelee/anaconda3/envs/syu_capstone_2022_1_2/lib/python3.9/json/encoder.py", line 257, in iterencode
    return _iterencode(o, 0)
  File "/Users/chaelee/anaconda3/envs/syu_capstone_2022_1_2/lib/python3.9/site-packages/django/core/serializers/json.py", line 106, in default
    return super().default(o)
  File "/Users/chaelee/anaconda3/envs/syu_capstone_2022_1_2/lib/python3.9/json/encoder.py", line 179, in default
    raise TypeError(f'Object of type {o.__class__.__name__} '
TypeError: Object of type set is not JSON serializable


25/May/2023 21:32:18,361 [ERROR] django.request: [35;1m[35;1mInternal Server Error: /handler/image-upload[0m[0m
Traceback (most recent call last):
  File "/Users/chaelee/PycharmProjects/syu_capstone_2022_1_2/BloomingMind/Handler/views.py", line 49, in post
    image_save(image_file=image_file)
  File "/Users/chaelee/PycharmProjects/syu_capstone_2022_1_2/BloomingMind/Handler/views.py", line 102, in image_save
    raise ImageFIleError('This file cannot be read.')
Handler.exceptions.ImageFIleError: This file cannot be read.

During handling of the above exception, another exception occurred:

Traceback (most recent call last):
  File "/Users/chaelee/anaconda3/envs/syu_capstone_2022_1_2/lib/python3.9/site-packages/asgiref/sync.py", line 486, in thread_handler
    raise exc_info[1]
  File "/Users/chaelee/anaconda3/envs/syu_capstone_2022_1_2/lib/python3.9/site-packages/django/core/handlers/exception.py", line 42, in inner
    response = await get_response(request)
  File "/Users/chaelee/anaconda3/envs/syu_capstone_2022_1_2/lib/python3.9/site-packages/django/core/handlers/base.py", line 253, in _get_response_async
    response = await wrapped_callback(
  File "/Users/chaelee/anaconda3/envs/syu_capstone_2022_1_2/lib/python3.9/site-packages/asgiref/sync.py", line 448, in __call__
    ret = await asyncio.wait_for(future, timeout=None)
  File "/Users/chaelee/anaconda3/envs/syu_capstone_2022_1_2/lib/python3.9/asyncio/tasks.py", line 442, in wait_for
    return await fut
  File "/Users/chaelee/anaconda3/envs/syu_capstone_2022_1_2/lib/python3.9/site-packages/asgiref/current_thread_executor.py", line 22, in run
    result = self.fn(*self.args, **self.kwargs)
  File "/Users/chaelee/anaconda3/envs/syu_capstone_2022_1_2/lib/python3.9/site-packages/asgiref/sync.py", line 490, in thread_handler
    return func(*args, **kwargs)
  File "/Users/chaelee/anaconda3/envs/syu_capstone_2022_1_2/lib/python3.9/site-packages/django/views/generic/base.py", line 104, in view
    return self.dispatch(request, *args, **kwargs)
  File "/Users/chaelee/anaconda3/envs/syu_capstone_2022_1_2/lib/python3.9/site-packages/django/views/generic/base.py", line 143, in dispatch
    return handler(request, *args, **kwargs)
  File "/Users/chaelee/anaconda3/envs/syu_capstone_2022_1_2/lib/python3.9/site-packages/django/views/decorators/csrf.py", line 56, in wrapper_view
    return view_func(*args, **kwargs)
  File "/Users/chaelee/PycharmProjects/syu_capstone_2022_1_2/BloomingMind/Handler/views.py", line 63, in post
    return JsonResponse(
  File "/Users/chaelee/anaconda3/envs/syu_capstone_2022_1_2/lib/python3.9/site-packages/django/http/response.py", line 748, in __init__
    data = json.dumps(data, cls=encoder, **json_dumps_params)
  File "/Users/chaelee/anaconda3/envs/syu_capstone_2022_1_2/lib/python3.9/json/__init__.py", line 234, in dumps
    return cls(
  File "/Users/chaelee/anaconda3/envs/syu_capstone_2022_1_2/lib/python3.9/json/encoder.py", line 199, in encode
    chunks = self.iterencode(o, _one_shot=True)
  File "/Users/chaelee/anaconda3/envs/syu_capstone_2022_1_2/lib/python3.9/json/encoder.py", line 257, in iterencode
    return _iterencode(o, 0)
  File "/Users/chaelee/anaconda3/envs/syu_capstone_2022_1_2/lib/python3.9/site-packages/django/core/serializers/json.py", line 106, in default
    return super().default(o)
  File "/Users/chaelee/anaconda3/envs/syu_capstone_2022_1_2/lib/python3.9/json/encoder.py", line 179, in default
    raise TypeError(f'Object of type {o.__class__.__name__} '
TypeError: Object of type set is not JSON serializable


25/May/2023 21:32:53,526 [ERROR] django.request: [35;1m[35;1mInternal Server Error: /handler/image-upload[0m[0m
Traceback (most recent call last):
  File "/Users/chaelee/PycharmProjects/syu_capstone_2022_1_2/BloomingMind/Handler/views.py", line 49, in post
    image_save(image_file=image_file)
  File "/Users/chaelee/PycharmProjects/syu_capstone_2022_1_2/BloomingMind/Handler/views.py", line 103, in image_save
    raise ImageFIleError('This file cannot be read.')
Handler.exceptions.ImageFIleError: This file cannot be read.

During handling of the above exception, another exception occurred:

Traceback (most recent call last):
  File "/Users/chaelee/anaconda3/envs/syu_capstone_2022_1_2/lib/python3.9/site-packages/asgiref/sync.py", line 486, in thread_handler
    raise exc_info[1]
  File "/Users/chaelee/anaconda3/envs/syu_capstone_2022_1_2/lib/python3.9/site-packages/django/core/handlers/exception.py", line 42, in inner
    response = await get_response(request)
  File "/Users/chaelee/anaconda3/envs/syu_capstone_2022_1_2/lib/python3.9/site-packages/django/core/handlers/base.py", line 253, in _get_response_async
    response = await wrapped_callback(
  File "/Users/chaelee/anaconda3/envs/syu_capstone_2022_1_2/lib/python3.9/site-packages/asgiref/sync.py", line 448, in __call__
    ret = await asyncio.wait_for(future, timeout=None)
  File "/Users/chaelee/anaconda3/envs/syu_capstone_2022_1_2/lib/python3.9/asyncio/tasks.py", line 442, in wait_for
    return await fut
  File "/Users/chaelee/anaconda3/envs/syu_capstone_2022_1_2/lib/python3.9/site-packages/asgiref/current_thread_executor.py", line 22, in run
    result = self.fn(*self.args, **self.kwargs)
  File "/Users/chaelee/anaconda3/envs/syu_capstone_2022_1_2/lib/python3.9/site-packages/asgiref/sync.py", line 490, in thread_handler
    return func(*args, **kwargs)
  File "/Users/chaelee/anaconda3/envs/syu_capstone_2022_1_2/lib/python3.9/site-packages/django/views/generic/base.py", line 104, in view
    return self.dispatch(request, *args, **kwargs)
  File "/Users/chaelee/anaconda3/envs/syu_capstone_2022_1_2/lib/python3.9/site-packages/django/views/generic/base.py", line 143, in dispatch
    return handler(request, *args, **kwargs)
  File "/Users/chaelee/anaconda3/envs/syu_capstone_2022_1_2/lib/python3.9/site-packages/django/views/decorators/csrf.py", line 56, in wrapper_view
    return view_func(*args, **kwargs)
  File "/Users/chaelee/PycharmProjects/syu_capstone_2022_1_2/BloomingMind/Handler/views.py", line 63, in post
    return JsonResponse(
  File "/Users/chaelee/anaconda3/envs/syu_capstone_2022_1_2/lib/python3.9/site-packages/django/http/response.py", line 748, in __init__
    data = json.dumps(data, cls=encoder, **json_dumps_params)
  File "/Users/chaelee/anaconda3/envs/syu_capstone_2022_1_2/lib/python3.9/json/__init__.py", line 234, in dumps
    return cls(
  File "/Users/chaelee/anaconda3/envs/syu_capstone_2022_1_2/lib/python3.9/json/encoder.py", line 199, in encode
    chunks = self.iterencode(o, _one_shot=True)
  File "/Users/chaelee/anaconda3/envs/syu_capstone_2022_1_2/lib/python3.9/json/encoder.py", line 257, in iterencode
    return _iterencode(o, 0)
  File "/Users/chaelee/anaconda3/envs/syu_capstone_2022_1_2/lib/python3.9/site-packages/django/core/serializers/json.py", line 106, in default
    return super().default(o)
  File "/Users/chaelee/anaconda3/envs/syu_capstone_2022_1_2/lib/python3.9/json/encoder.py", line 179, in default
    raise TypeError(f'Object of type {o.__class__.__name__} '
TypeError: Object of type set is not JSON serializable


25/May/2023 21:33:17,343 [ERROR] django.request: [35;1m[35;1mInternal Server Error: /handler/image-upload[0m[0m
Traceback (most recent call last):
  File "/Users/chaelee/PycharmProjects/syu_capstone_2022_1_2/BloomingMind/Handler/views.py", line 49, in post
    image_save(image_file=image_file)
  File "/Users/chaelee/PycharmProjects/syu_capstone_2022_1_2/BloomingMind/Handler/views.py", line 103, in image_save
    raise ImageFIleError('This file cannot be read.')
Handler.exceptions.ImageFIleError: This file cannot be read.

During handling of the above exception, another exception occurred:

Traceback (most recent call last):
  File "/Users/chaelee/anaconda3/envs/syu_capstone_2022_1_2/lib/python3.9/site-packages/asgiref/sync.py", line 486, in thread_handler
    raise exc_info[1]
  File "/Users/chaelee/anaconda3/envs/syu_capstone_2022_1_2/lib/python3.9/site-packages/django/core/handlers/exception.py", line 42, in inner
    response = await get_response(request)
  File "/Users/chaelee/anaconda3/envs/syu_capstone_2022_1_2/lib/python3.9/site-packages/django/core/handlers/base.py", line 253, in _get_response_async
    response = await wrapped_callback(
  File "/Users/chaelee/anaconda3/envs/syu_capstone_2022_1_2/lib/python3.9/site-packages/asgiref/sync.py", line 448, in __call__
    ret = await asyncio.wait_for(future, timeout=None)
  File "/Users/chaelee/anaconda3/envs/syu_capstone_2022_1_2/lib/python3.9/asyncio/tasks.py", line 442, in wait_for
    return await fut
  File "/Users/chaelee/anaconda3/envs/syu_capstone_2022_1_2/lib/python3.9/site-packages/asgiref/current_thread_executor.py", line 22, in run
    result = self.fn(*self.args, **self.kwargs)
  File "/Users/chaelee/anaconda3/envs/syu_capstone_2022_1_2/lib/python3.9/site-packages/asgiref/sync.py", line 490, in thread_handler
    return func(*args, **kwargs)
  File "/Users/chaelee/anaconda3/envs/syu_capstone_2022_1_2/lib/python3.9/site-packages/django/views/generic/base.py", line 104, in view
    return self.dispatch(request, *args, **kwargs)
  File "/Users/chaelee/anaconda3/envs/syu_capstone_2022_1_2/lib/python3.9/site-packages/django/views/generic/base.py", line 143, in dispatch
    return handler(request, *args, **kwargs)
  File "/Users/chaelee/anaconda3/envs/syu_capstone_2022_1_2/lib/python3.9/site-packages/django/views/decorators/csrf.py", line 56, in wrapper_view
    return view_func(*args, **kwargs)
  File "/Users/chaelee/PycharmProjects/syu_capstone_2022_1_2/BloomingMind/Handler/views.py", line 63, in post
    return JsonResponse(
  File "/Users/chaelee/anaconda3/envs/syu_capstone_2022_1_2/lib/python3.9/site-packages/django/http/response.py", line 748, in __init__
    data = json.dumps(data, cls=encoder, **json_dumps_params)
  File "/Users/chaelee/anaconda3/envs/syu_capstone_2022_1_2/lib/python3.9/json/__init__.py", line 234, in dumps
    return cls(
  File "/Users/chaelee/anaconda3/envs/syu_capstone_2022_1_2/lib/python3.9/json/encoder.py", line 199, in encode
    chunks = self.iterencode(o, _one_shot=True)
  File "/Users/chaelee/anaconda3/envs/syu_capstone_2022_1_2/lib/python3.9/json/encoder.py", line 257, in iterencode
    return _iterencode(o, 0)
  File "/Users/chaelee/anaconda3/envs/syu_capstone_2022_1_2/lib/python3.9/site-packages/django/core/serializers/json.py", line 106, in default
    return super().default(o)
  File "/Users/chaelee/anaconda3/envs/syu_capstone_2022_1_2/lib/python3.9/json/encoder.py", line 179, in default
    raise TypeError(f'Object of type {o.__class__.__name__} '
TypeError: Object of type set is not JSON serializable


25/May/2023 21:33:34,177 [ERROR] django.request: [35;1m[35;1mInternal Server Error: /handler/image-upload[0m[0m
Traceback (most recent call last):
  File "/Users/chaelee/PycharmProjects/syu_capstone_2022_1_2/BloomingMind/Handler/views.py", line 111, in image_save
    if image_name.endswith('jp', 'jpeg'):
TypeError: slice indices must be integers or None or have an __index__ method

During handling of the above exception, another exception occurred:

Traceback (most recent call last):
  File "/Users/chaelee/PycharmProjects/syu_capstone_2022_1_2/BloomingMind/Handler/views.py", line 49, in post
    image_save(image_file=image_file)
  File "/Users/chaelee/PycharmProjects/syu_capstone_2022_1_2/BloomingMind/Handler/views.py", line 118, in image_save
    raise ImageFIleError('This file cannot be read.')
Handler.exceptions.ImageFIleError: This file cannot be read.

During handling of the above exception, another exception occurred:

Traceback (most recent call last):
  File "/Users/chaelee/anaconda3/envs/syu_capstone_2022_1_2/lib/python3.9/site-packages/asgiref/sync.py", line 486, in thread_handler
    raise exc_info[1]
  File "/Users/chaelee/anaconda3/envs/syu_capstone_2022_1_2/lib/python3.9/site-packages/django/core/handlers/exception.py", line 42, in inner
    response = await get_response(request)
  File "/Users/chaelee/anaconda3/envs/syu_capstone_2022_1_2/lib/python3.9/site-packages/django/core/handlers/base.py", line 253, in _get_response_async
    response = await wrapped_callback(
  File "/Users/chaelee/anaconda3/envs/syu_capstone_2022_1_2/lib/python3.9/site-packages/asgiref/sync.py", line 448, in __call__
    ret = await asyncio.wait_for(future, timeout=None)
  File "/Users/chaelee/anaconda3/envs/syu_capstone_2022_1_2/lib/python3.9/asyncio/tasks.py", line 442, in wait_for
    return await fut
  File "/Users/chaelee/anaconda3/envs/syu_capstone_2022_1_2/lib/python3.9/site-packages/asgiref/current_thread_executor.py", line 22, in run
    result = self.fn(*self.args, **self.kwargs)
  File "/Users/chaelee/anaconda3/envs/syu_capstone_2022_1_2/lib/python3.9/site-packages/asgiref/sync.py", line 490, in thread_handler
    return func(*args, **kwargs)
  File "/Users/chaelee/anaconda3/envs/syu_capstone_2022_1_2/lib/python3.9/site-packages/django/views/generic/base.py", line 104, in view
    return self.dispatch(request, *args, **kwargs)
  File "/Users/chaelee/anaconda3/envs/syu_capstone_2022_1_2/lib/python3.9/site-packages/django/views/generic/base.py", line 143, in dispatch
    return handler(request, *args, **kwargs)
  File "/Users/chaelee/anaconda3/envs/syu_capstone_2022_1_2/lib/python3.9/site-packages/django/views/decorators/csrf.py", line 56, in wrapper_view
    return view_func(*args, **kwargs)
  File "/Users/chaelee/PycharmProjects/syu_capstone_2022_1_2/BloomingMind/Handler/views.py", line 63, in post
    return JsonResponse(
  File "/Users/chaelee/anaconda3/envs/syu_capstone_2022_1_2/lib/python3.9/site-packages/django/http/response.py", line 748, in __init__
    data = json.dumps(data, cls=encoder, **json_dumps_params)
  File "/Users/chaelee/anaconda3/envs/syu_capstone_2022_1_2/lib/python3.9/json/__init__.py", line 234, in dumps
    return cls(
  File "/Users/chaelee/anaconda3/envs/syu_capstone_2022_1_2/lib/python3.9/json/encoder.py", line 199, in encode
    chunks = self.iterencode(o, _one_shot=True)
  File "/Users/chaelee/anaconda3/envs/syu_capstone_2022_1_2/lib/python3.9/json/encoder.py", line 257, in iterencode
    return _iterencode(o, 0)
  File "/Users/chaelee/anaconda3/envs/syu_capstone_2022_1_2/lib/python3.9/site-packages/django/core/serializers/json.py", line 106, in default
    return super().default(o)
  File "/Users/chaelee/anaconda3/envs/syu_capstone_2022_1_2/lib/python3.9/json/encoder.py", line 179, in default
    raise TypeError(f'Object of type {o.__class__.__name__} '
TypeError: Object of type set is not JSON serializable


25/May/2023 21:34:21,786 [ERROR] django.request: [35;1m[35;1mInternal Server Error: /handler/image-upload[0m[0m
Traceback (most recent call last):
  File "/Users/chaelee/PycharmProjects/syu_capstone_2022_1_2/BloomingMind/Handler/views.py", line 111, in image_save
    image_bytes = image_conversion(image_file)
TypeError: slice indices must be integers or None or have an __index__ method

During handling of the above exception, another exception occurred:

Traceback (most recent call last):
  File "/Users/chaelee/PycharmProjects/syu_capstone_2022_1_2/BloomingMind/Handler/views.py", line 49, in post
    image_save(image_file=image_file)
  File "/Users/chaelee/PycharmProjects/syu_capstone_2022_1_2/BloomingMind/Handler/views.py", line 118, in image_save
Handler.exceptions.ImageFIleError: This file cannot be read.

During handling of the above exception, another exception occurred:

Traceback (most recent call last):
  File "/Users/chaelee/anaconda3/envs/syu_capstone_2022_1_2/lib/python3.9/site-packages/asgiref/sync.py", line 486, in thread_handler
    raise exc_info[1]
  File "/Users/chaelee/anaconda3/envs/syu_capstone_2022_1_2/lib/python3.9/site-packages/django/core/handlers/exception.py", line 42, in inner
    response = await get_response(request)
  File "/Users/chaelee/anaconda3/envs/syu_capstone_2022_1_2/lib/python3.9/site-packages/django/core/handlers/base.py", line 253, in _get_response_async
    response = await wrapped_callback(
  File "/Users/chaelee/anaconda3/envs/syu_capstone_2022_1_2/lib/python3.9/site-packages/asgiref/sync.py", line 448, in __call__
    ret = await asyncio.wait_for(future, timeout=None)
  File "/Users/chaelee/anaconda3/envs/syu_capstone_2022_1_2/lib/python3.9/asyncio/tasks.py", line 442, in wait_for
    return await fut
  File "/Users/chaelee/anaconda3/envs/syu_capstone_2022_1_2/lib/python3.9/site-packages/asgiref/current_thread_executor.py", line 22, in run
    result = self.fn(*self.args, **self.kwargs)
  File "/Users/chaelee/anaconda3/envs/syu_capstone_2022_1_2/lib/python3.9/site-packages/asgiref/sync.py", line 490, in thread_handler
    return func(*args, **kwargs)
  File "/Users/chaelee/anaconda3/envs/syu_capstone_2022_1_2/lib/python3.9/site-packages/django/views/generic/base.py", line 104, in view
    return self.dispatch(request, *args, **kwargs)
  File "/Users/chaelee/anaconda3/envs/syu_capstone_2022_1_2/lib/python3.9/site-packages/django/views/generic/base.py", line 143, in dispatch
    return handler(request, *args, **kwargs)
  File "/Users/chaelee/anaconda3/envs/syu_capstone_2022_1_2/lib/python3.9/site-packages/django/views/decorators/csrf.py", line 56, in wrapper_view
    return view_func(*args, **kwargs)
  File "/Users/chaelee/PycharmProjects/syu_capstone_2022_1_2/BloomingMind/Handler/views.py", line 63, in post
    return JsonResponse(
  File "/Users/chaelee/anaconda3/envs/syu_capstone_2022_1_2/lib/python3.9/site-packages/django/http/response.py", line 748, in __init__
    data = json.dumps(data, cls=encoder, **json_dumps_params)
  File "/Users/chaelee/anaconda3/envs/syu_capstone_2022_1_2/lib/python3.9/json/__init__.py", line 234, in dumps
    return cls(
  File "/Users/chaelee/anaconda3/envs/syu_capstone_2022_1_2/lib/python3.9/json/encoder.py", line 199, in encode
    chunks = self.iterencode(o, _one_shot=True)
  File "/Users/chaelee/anaconda3/envs/syu_capstone_2022_1_2/lib/python3.9/json/encoder.py", line 257, in iterencode
    return _iterencode(o, 0)
  File "/Users/chaelee/anaconda3/envs/syu_capstone_2022_1_2/lib/python3.9/site-packages/django/core/serializers/json.py", line 106, in default
    return super().default(o)
  File "/Users/chaelee/anaconda3/envs/syu_capstone_2022_1_2/lib/python3.9/json/encoder.py", line 179, in default
    raise TypeError(f'Object of type {o.__class__.__name__} '
TypeError: Object of type set is not JSON serializable


25/May/2023 21:35:37,453 [ERROR] django.request: [35;1m[35;1mInternal Server Error: /handler/image-upload[0m[0m
Traceback (most recent call last):
  File "/Users/chaelee/PycharmProjects/syu_capstone_2022_1_2/BloomingMind/Handler/views.py", line 49, in post
    image_save(image_file=image_file)
  File "/Users/chaelee/PycharmProjects/syu_capstone_2022_1_2/BloomingMind/Handler/views.py", line 102, in image_save
    raise ImageFIleError('This file cannot be read.')
Handler.exceptions.ImageFIleError: This file cannot be read.

During handling of the above exception, another exception occurred:

Traceback (most recent call last):
  File "/Users/chaelee/anaconda3/envs/syu_capstone_2022_1_2/lib/python3.9/site-packages/asgiref/sync.py", line 486, in thread_handler
    raise exc_info[1]
  File "/Users/chaelee/anaconda3/envs/syu_capstone_2022_1_2/lib/python3.9/site-packages/django/core/handlers/exception.py", line 42, in inner
    response = await get_response(request)
  File "/Users/chaelee/anaconda3/envs/syu_capstone_2022_1_2/lib/python3.9/site-packages/django/core/handlers/base.py", line 253, in _get_response_async
    response = await wrapped_callback(
  File "/Users/chaelee/anaconda3/envs/syu_capstone_2022_1_2/lib/python3.9/site-packages/asgiref/sync.py", line 448, in __call__
    ret = await asyncio.wait_for(future, timeout=None)
  File "/Users/chaelee/anaconda3/envs/syu_capstone_2022_1_2/lib/python3.9/asyncio/tasks.py", line 442, in wait_for
    return await fut
  File "/Users/chaelee/anaconda3/envs/syu_capstone_2022_1_2/lib/python3.9/site-packages/asgiref/current_thread_executor.py", line 22, in run
    result = self.fn(*self.args, **self.kwargs)
  File "/Users/chaelee/anaconda3/envs/syu_capstone_2022_1_2/lib/python3.9/site-packages/asgiref/sync.py", line 490, in thread_handler
    return func(*args, **kwargs)
  File "/Users/chaelee/anaconda3/envs/syu_capstone_2022_1_2/lib/python3.9/site-packages/django/views/generic/base.py", line 104, in view
    return self.dispatch(request, *args, **kwargs)
  File "/Users/chaelee/anaconda3/envs/syu_capstone_2022_1_2/lib/python3.9/site-packages/django/views/generic/base.py", line 143, in dispatch
    return handler(request, *args, **kwargs)
  File "/Users/chaelee/anaconda3/envs/syu_capstone_2022_1_2/lib/python3.9/site-packages/django/views/decorators/csrf.py", line 56, in wrapper_view
    return view_func(*args, **kwargs)
  File "/Users/chaelee/PycharmProjects/syu_capstone_2022_1_2/BloomingMind/Handler/views.py", line 63, in post
    return JsonResponse(
  File "/Users/chaelee/anaconda3/envs/syu_capstone_2022_1_2/lib/python3.9/site-packages/django/http/response.py", line 748, in __init__
    data = json.dumps(data, cls=encoder, **json_dumps_params)
  File "/Users/chaelee/anaconda3/envs/syu_capstone_2022_1_2/lib/python3.9/json/__init__.py", line 234, in dumps
    return cls(
  File "/Users/chaelee/anaconda3/envs/syu_capstone_2022_1_2/lib/python3.9/json/encoder.py", line 199, in encode
    chunks = self.iterencode(o, _one_shot=True)
  File "/Users/chaelee/anaconda3/envs/syu_capstone_2022_1_2/lib/python3.9/json/encoder.py", line 257, in iterencode
    return _iterencode(o, 0)
  File "/Users/chaelee/anaconda3/envs/syu_capstone_2022_1_2/lib/python3.9/site-packages/django/core/serializers/json.py", line 106, in default
    return super().default(o)
  File "/Users/chaelee/anaconda3/envs/syu_capstone_2022_1_2/lib/python3.9/json/encoder.py", line 179, in default
    raise TypeError(f'Object of type {o.__class__.__name__} '
TypeError: Object of type set is not JSON serializable


25/May/2023 21:39:50,725 [ERROR] django.request: [35;1m[35;1mInternal Server Error: /handler/image-upload[0m[0m
Traceback (most recent call last):
  File "/Users/chaelee/PycharmProjects/syu_capstone_2022_1_2/BloomingMind/Handler/views.py", line 49, in post
    image_save(image_file=image_file)
  File "/Users/chaelee/PycharmProjects/syu_capstone_2022_1_2/BloomingMind/Handler/views.py", line 102, in image_save
    raise ImageFIleError('This file cannot be read.')
Handler.exceptions.ImageFIleError: This file cannot be read.

During handling of the above exception, another exception occurred:

Traceback (most recent call last):
  File "/Users/chaelee/anaconda3/envs/syu_capstone_2022_1_2/lib/python3.9/site-packages/asgiref/sync.py", line 486, in thread_handler
    raise exc_info[1]
  File "/Users/chaelee/anaconda3/envs/syu_capstone_2022_1_2/lib/python3.9/site-packages/django/core/handlers/exception.py", line 42, in inner
    response = await get_response(request)
  File "/Users/chaelee/anaconda3/envs/syu_capstone_2022_1_2/lib/python3.9/site-packages/django/core/handlers/base.py", line 253, in _get_response_async
    response = await wrapped_callback(
  File "/Users/chaelee/anaconda3/envs/syu_capstone_2022_1_2/lib/python3.9/site-packages/asgiref/sync.py", line 448, in __call__
    ret = await asyncio.wait_for(future, timeout=None)
  File "/Users/chaelee/anaconda3/envs/syu_capstone_2022_1_2/lib/python3.9/asyncio/tasks.py", line 442, in wait_for
    return await fut
  File "/Users/chaelee/anaconda3/envs/syu_capstone_2022_1_2/lib/python3.9/site-packages/asgiref/current_thread_executor.py", line 22, in run
    result = self.fn(*self.args, **self.kwargs)
  File "/Users/chaelee/anaconda3/envs/syu_capstone_2022_1_2/lib/python3.9/site-packages/asgiref/sync.py", line 490, in thread_handler
    return func(*args, **kwargs)
  File "/Users/chaelee/anaconda3/envs/syu_capstone_2022_1_2/lib/python3.9/site-packages/django/views/generic/base.py", line 104, in view
    return self.dispatch(request, *args, **kwargs)
  File "/Users/chaelee/anaconda3/envs/syu_capstone_2022_1_2/lib/python3.9/site-packages/django/views/generic/base.py", line 143, in dispatch
    return handler(request, *args, **kwargs)
  File "/Users/chaelee/anaconda3/envs/syu_capstone_2022_1_2/lib/python3.9/site-packages/django/views/decorators/csrf.py", line 56, in wrapper_view
    return view_func(*args, **kwargs)
  File "/Users/chaelee/PycharmProjects/syu_capstone_2022_1_2/BloomingMind/Handler/views.py", line 63, in post
    return JsonResponse(
  File "/Users/chaelee/anaconda3/envs/syu_capstone_2022_1_2/lib/python3.9/site-packages/django/http/response.py", line 748, in __init__
    data = json.dumps(data, cls=encoder, **json_dumps_params)
  File "/Users/chaelee/anaconda3/envs/syu_capstone_2022_1_2/lib/python3.9/json/__init__.py", line 234, in dumps
    return cls(
  File "/Users/chaelee/anaconda3/envs/syu_capstone_2022_1_2/lib/python3.9/json/encoder.py", line 199, in encode
    chunks = self.iterencode(o, _one_shot=True)
  File "/Users/chaelee/anaconda3/envs/syu_capstone_2022_1_2/lib/python3.9/json/encoder.py", line 257, in iterencode
    return _iterencode(o, 0)
  File "/Users/chaelee/anaconda3/envs/syu_capstone_2022_1_2/lib/python3.9/site-packages/django/core/serializers/json.py", line 106, in default
    return super().default(o)
  File "/Users/chaelee/anaconda3/envs/syu_capstone_2022_1_2/lib/python3.9/json/encoder.py", line 179, in default
    raise TypeError(f'Object of type {o.__class__.__name__} '
TypeError: Object of type set is not JSON serializable


25/May/2023 21:40:57,403 [ERROR] django.request: [35;1m[35;1mInternal Server Error: /handler/image-upload[0m[0m
Traceback (most recent call last):
  File "/Users/chaelee/PycharmProjects/syu_capstone_2022_1_2/BloomingMind/Handler/views.py", line 49, in post
    image_save(image_file=image_file)
  File "/Users/chaelee/PycharmProjects/syu_capstone_2022_1_2/BloomingMind/Handler/views.py", line 103, in image_save
    raise ImageFIleError('This file cannot be read.')
Handler.exceptions.ImageFIleError: This file cannot be read.

During handling of the above exception, another exception occurred:

Traceback (most recent call last):
  File "/Users/chaelee/anaconda3/envs/syu_capstone_2022_1_2/lib/python3.9/site-packages/asgiref/sync.py", line 486, in thread_handler
    raise exc_info[1]
  File "/Users/chaelee/anaconda3/envs/syu_capstone_2022_1_2/lib/python3.9/site-packages/django/core/handlers/exception.py", line 42, in inner
    response = await get_response(request)
  File "/Users/chaelee/anaconda3/envs/syu_capstone_2022_1_2/lib/python3.9/site-packages/django/core/handlers/base.py", line 253, in _get_response_async
    response = await wrapped_callback(
  File "/Users/chaelee/anaconda3/envs/syu_capstone_2022_1_2/lib/python3.9/site-packages/asgiref/sync.py", line 448, in __call__
    ret = await asyncio.wait_for(future, timeout=None)
  File "/Users/chaelee/anaconda3/envs/syu_capstone_2022_1_2/lib/python3.9/asyncio/tasks.py", line 442, in wait_for
    return await fut
  File "/Users/chaelee/anaconda3/envs/syu_capstone_2022_1_2/lib/python3.9/site-packages/asgiref/current_thread_executor.py", line 22, in run
    result = self.fn(*self.args, **self.kwargs)
  File "/Users/chaelee/anaconda3/envs/syu_capstone_2022_1_2/lib/python3.9/site-packages/asgiref/sync.py", line 490, in thread_handler
    return func(*args, **kwargs)
  File "/Users/chaelee/anaconda3/envs/syu_capstone_2022_1_2/lib/python3.9/site-packages/django/views/generic/base.py", line 104, in view
    return self.dispatch(request, *args, **kwargs)
  File "/Users/chaelee/anaconda3/envs/syu_capstone_2022_1_2/lib/python3.9/site-packages/django/views/generic/base.py", line 143, in dispatch
    return handler(request, *args, **kwargs)
  File "/Users/chaelee/anaconda3/envs/syu_capstone_2022_1_2/lib/python3.9/site-packages/django/views/decorators/csrf.py", line 56, in wrapper_view
    return view_func(*args, **kwargs)
  File "/Users/chaelee/PycharmProjects/syu_capstone_2022_1_2/BloomingMind/Handler/views.py", line 64, in post
    return JsonResponse(
  File "/Users/chaelee/anaconda3/envs/syu_capstone_2022_1_2/lib/python3.9/site-packages/django/http/response.py", line 748, in __init__
    data = json.dumps(data, cls=encoder, **json_dumps_params)
  File "/Users/chaelee/anaconda3/envs/syu_capstone_2022_1_2/lib/python3.9/json/__init__.py", line 234, in dumps
    return cls(
  File "/Users/chaelee/anaconda3/envs/syu_capstone_2022_1_2/lib/python3.9/json/encoder.py", line 199, in encode
    chunks = self.iterencode(o, _one_shot=True)
  File "/Users/chaelee/anaconda3/envs/syu_capstone_2022_1_2/lib/python3.9/json/encoder.py", line 257, in iterencode
    return _iterencode(o, 0)
  File "/Users/chaelee/anaconda3/envs/syu_capstone_2022_1_2/lib/python3.9/site-packages/django/core/serializers/json.py", line 106, in default
    return super().default(o)
  File "/Users/chaelee/anaconda3/envs/syu_capstone_2022_1_2/lib/python3.9/json/encoder.py", line 179, in default
    raise TypeError(f'Object of type {o.__class__.__name__} '
TypeError: Object of type set is not JSON serializable


25/May/2023 21:41:27,807 [ERROR] django.request: [35;1m[35;1mInternal Server Error: /handler/image-upload[0m[0m
Traceback (most recent call last):
  File "/Users/chaelee/PycharmProjects/syu_capstone_2022_1_2/BloomingMind/Handler/views.py", line 49, in post
    image_save(image_file=image_file)
  File "/Users/chaelee/PycharmProjects/syu_capstone_2022_1_2/BloomingMind/Handler/views.py", line 102, in image_save
    raise ImageFIleError('This file cannot be read.')
Handler.exceptions.ImageFIleError: This file cannot be read.

During handling of the above exception, another exception occurred:

Traceback (most recent call last):
  File "/Users/chaelee/anaconda3/envs/syu_capstone_2022_1_2/lib/python3.9/site-packages/asgiref/sync.py", line 486, in thread_handler
    raise exc_info[1]
  File "/Users/chaelee/anaconda3/envs/syu_capstone_2022_1_2/lib/python3.9/site-packages/django/core/handlers/exception.py", line 42, in inner
    response = await get_response(request)
  File "/Users/chaelee/anaconda3/envs/syu_capstone_2022_1_2/lib/python3.9/site-packages/django/core/handlers/base.py", line 253, in _get_response_async
    response = await wrapped_callback(
  File "/Users/chaelee/anaconda3/envs/syu_capstone_2022_1_2/lib/python3.9/site-packages/asgiref/sync.py", line 448, in __call__
    ret = await asyncio.wait_for(future, timeout=None)
  File "/Users/chaelee/anaconda3/envs/syu_capstone_2022_1_2/lib/python3.9/asyncio/tasks.py", line 442, in wait_for
    return await fut
  File "/Users/chaelee/anaconda3/envs/syu_capstone_2022_1_2/lib/python3.9/site-packages/asgiref/current_thread_executor.py", line 22, in run
    result = self.fn(*self.args, **self.kwargs)
  File "/Users/chaelee/anaconda3/envs/syu_capstone_2022_1_2/lib/python3.9/site-packages/asgiref/sync.py", line 490, in thread_handler
    return func(*args, **kwargs)
  File "/Users/chaelee/anaconda3/envs/syu_capstone_2022_1_2/lib/python3.9/site-packages/django/views/generic/base.py", line 104, in view
    return self.dispatch(request, *args, **kwargs)
  File "/Users/chaelee/anaconda3/envs/syu_capstone_2022_1_2/lib/python3.9/site-packages/django/views/generic/base.py", line 143, in dispatch
    return handler(request, *args, **kwargs)
  File "/Users/chaelee/anaconda3/envs/syu_capstone_2022_1_2/lib/python3.9/site-packages/django/views/decorators/csrf.py", line 56, in wrapper_view
    return view_func(*args, **kwargs)
  File "/Users/chaelee/PycharmProjects/syu_capstone_2022_1_2/BloomingMind/Handler/views.py", line 63, in post
    return JsonResponse(
  File "/Users/chaelee/anaconda3/envs/syu_capstone_2022_1_2/lib/python3.9/site-packages/django/http/response.py", line 748, in __init__
    data = json.dumps(data, cls=encoder, **json_dumps_params)
  File "/Users/chaelee/anaconda3/envs/syu_capstone_2022_1_2/lib/python3.9/json/__init__.py", line 234, in dumps
    return cls(
  File "/Users/chaelee/anaconda3/envs/syu_capstone_2022_1_2/lib/python3.9/json/encoder.py", line 199, in encode
    chunks = self.iterencode(o, _one_shot=True)
  File "/Users/chaelee/anaconda3/envs/syu_capstone_2022_1_2/lib/python3.9/json/encoder.py", line 257, in iterencode
    return _iterencode(o, 0)
  File "/Users/chaelee/anaconda3/envs/syu_capstone_2022_1_2/lib/python3.9/site-packages/django/core/serializers/json.py", line 106, in default
    return super().default(o)
  File "/Users/chaelee/anaconda3/envs/syu_capstone_2022_1_2/lib/python3.9/json/encoder.py", line 179, in default
    raise TypeError(f'Object of type {o.__class__.__name__} '
TypeError: Object of type set is not JSON serializable
