

20/Apr/2023 19:36:26,675 [ERROR] django.request: [35;1m[35;1mInternal Server Error: /handler/image-upload[0m[0m
Traceback (most recent call last):
  File "/Users/chaelee/anaconda3/envs/syu_capstone_2022_1_2/lib/python3.9/site-packages/django/utils/datastructures.py", line 84, in __getitem__
    list_ = super().__getitem__(key)
KeyError: 'image'

During handling of the above exception, another exception occurred:

Traceback (most recent call last):
  File "/Users/chaelee/anaconda3/envs/syu_capstone_2022_1_2/lib/python3.9/site-packages/asgiref/sync.py", line 486, in thread_handler
    raise exc_info[1]
  File "/Users/chaelee/anaconda3/envs/syu_capstone_2022_1_2/lib/python3.9/site-packages/django/core/handlers/exception.py", line 42, in inner
    response = await get_response(request)
  File "/Users/chaelee/anaconda3/envs/syu_capstone_2022_1_2/lib/python3.9/site-packages/django/core/handlers/base.py", line 253, in _get_response_async
    response = await wrapped_callback(
  File "/Users/chaelee/anaconda3/envs/syu_capstone_2022_1_2/lib/python3.9/site-packages/asgiref/sync.py", line 448, in __call__
    ret = await asyncio.wait_for(future, timeout=None)
  File "/Users/chaelee/anaconda3/envs/syu_capstone_2022_1_2/lib/python3.9/asyncio/tasks.py", line 442, in wait_for
    return await fut
  File "/Users/chaelee/anaconda3/envs/syu_capstone_2022_1_2/lib/python3.9/site-packages/asgiref/current_thread_executor.py", line 22, in run
    result = self.fn(*self.args, **self.kwargs)
  File "/Users/chaelee/anaconda3/envs/syu_capstone_2022_1_2/lib/python3.9/site-packages/asgiref/sync.py", line 490, in thread_handler
    return func(*args, **kwargs)
  File "/Users/chaelee/anaconda3/envs/syu_capstone_2022_1_2/lib/python3.9/site-packages/django/views/generic/base.py", line 104, in view
    return self.dispatch(request, *args, **kwargs)
  File "/Users/chaelee/anaconda3/envs/syu_capstone_2022_1_2/lib/python3.9/site-packages/django/views/generic/base.py", line 143, in dispatch
    return handler(request, *args, **kwargs)
  File "/Users/chaelee/anaconda3/envs/syu_capstone_2022_1_2/lib/python3.9/site-packages/django/views/decorators/csrf.py", line 56, in wrapper_view
    return view_func(*args, **kwargs)
  File "/Users/chaelee/PycharmProjects/syu_capstone_2022_1_2/BloomingMind/Handler/views.py", line 46, in post
    if request.FILES['image']:
  File "/Users/chaelee/anaconda3/envs/syu_capstone_2022_1_2/lib/python3.9/site-packages/django/utils/datastructures.py", line 86, in __getitem__
    raise MultiValueDictKeyError(key)
django.utils.datastructures.MultiValueDictKeyError: 'image'


20/Apr/2023 19:37:43,997 [ERROR] django.request: [35;1m[35;1mInternal Server Error: /handler/image-upload[0m[0m
Traceback (most recent call last):
  File "/Users/chaelee/anaconda3/envs/syu_capstone_2022_1_2/lib/python3.9/site-packages/asgiref/sync.py", line 486, in thread_handler
    raise exc_info[1]
  File "/Users/chaelee/anaconda3/envs/syu_capstone_2022_1_2/lib/python3.9/site-packages/django/core/handlers/exception.py", line 42, in inner
    response = await get_response(request)
  File "/Users/chaelee/anaconda3/envs/syu_capstone_2022_1_2/lib/python3.9/site-packages/django/core/handlers/base.py", line 253, in _get_response_async
    response = await wrapped_callback(
  File "/Users/chaelee/anaconda3/envs/syu_capstone_2022_1_2/lib/python3.9/site-packages/asgiref/sync.py", line 448, in __call__
    ret = await asyncio.wait_for(future, timeout=None)
  File "/Users/chaelee/anaconda3/envs/syu_capstone_2022_1_2/lib/python3.9/asyncio/tasks.py", line 442, in wait_for
    return await fut
  File "/Users/chaelee/anaconda3/envs/syu_capstone_2022_1_2/lib/python3.9/site-packages/asgiref/current_thread_executor.py", line 22, in run
    result = self.fn(*self.args, **self.kwargs)
  File "/Users/chaelee/anaconda3/envs/syu_capstone_2022_1_2/lib/python3.9/site-packages/asgiref/sync.py", line 490, in thread_handler
    return func(*args, **kwargs)
  File "/Users/chaelee/anaconda3/envs/syu_capstone_2022_1_2/lib/python3.9/site-packages/django/views/generic/base.py", line 104, in view
    return self.dispatch(request, *args, **kwargs)
  File "/Users/chaelee/anaconda3/envs/syu_capstone_2022_1_2/lib/python3.9/site-packages/django/views/generic/base.py", line 143, in dispatch
    return handler(request, *args, **kwargs)
  File "/Users/chaelee/anaconda3/envs/syu_capstone_2022_1_2/lib/python3.9/site-packages/django/views/decorators/csrf.py", line 56, in wrapper_view
    return view_func(*args, **kwargs)
  File "/Users/chaelee/PycharmProjects/syu_capstone_2022_1_2/BloomingMind/Handler/views.py", line 48, in post
    data = json.loads(request.body)
  File "/Users/chaelee/anaconda3/envs/syu_capstone_2022_1_2/lib/python3.9/site-packages/django/http/request.py", line 344, in body
    raise RawPostDataException(
django.http.request.RawPostDataException: You cannot access body after reading from request's data stream


20/Apr/2023 19:39:30,658 [ERROR] django.request: [35;1m[35;1mInternal Server Error: /handler/image-upload[0m[0m
Traceback (most recent call last):
  File "/Users/chaelee/anaconda3/envs/syu_capstone_2022_1_2/lib/python3.9/site-packages/asgiref/sync.py", line 486, in thread_handler
    raise exc_info[1]
  File "/Users/chaelee/anaconda3/envs/syu_capstone_2022_1_2/lib/python3.9/site-packages/django/core/handlers/exception.py", line 42, in inner
    response = await get_response(request)
  File "/Users/chaelee/anaconda3/envs/syu_capstone_2022_1_2/lib/python3.9/site-packages/django/core/handlers/base.py", line 253, in _get_response_async
    response = await wrapped_callback(
  File "/Users/chaelee/anaconda3/envs/syu_capstone_2022_1_2/lib/python3.9/site-packages/asgiref/sync.py", line 448, in __call__
    ret = await asyncio.wait_for(future, timeout=None)
  File "/Users/chaelee/anaconda3/envs/syu_capstone_2022_1_2/lib/python3.9/asyncio/tasks.py", line 442, in wait_for
    return await fut
  File "/Users/chaelee/anaconda3/envs/syu_capstone_2022_1_2/lib/python3.9/site-packages/asgiref/current_thread_executor.py", line 22, in run
    result = self.fn(*self.args, **self.kwargs)
  File "/Users/chaelee/anaconda3/envs/syu_capstone_2022_1_2/lib/python3.9/site-packages/asgiref/sync.py", line 490, in thread_handler
    return func(*args, **kwargs)
  File "/Users/chaelee/anaconda3/envs/syu_capstone_2022_1_2/lib/python3.9/site-packages/django/views/generic/base.py", line 104, in view
    return self.dispatch(request, *args, **kwargs)
  File "/Users/chaelee/anaconda3/envs/syu_capstone_2022_1_2/lib/python3.9/site-packages/django/views/generic/base.py", line 143, in dispatch
    return handler(request, *args, **kwargs)
  File "/Users/chaelee/anaconda3/envs/syu_capstone_2022_1_2/lib/python3.9/site-packages/django/views/decorators/csrf.py", line 56, in wrapper_view
    return view_func(*args, **kwargs)
  File "/Users/chaelee/PycharmProjects/syu_capstone_2022_1_2/BloomingMind/Handler/views.py", line 49, in post
    data = json.loads(request.body)
  File "/Users/chaelee/anaconda3/envs/syu_capstone_2022_1_2/lib/python3.9/site-packages/django/http/request.py", line 344, in body
    raise RawPostDataException(
django.http.request.RawPostDataException: You cannot access body after reading from request's data stream


20/Apr/2023 19:39:59,399 [ERROR] django.request: [35;1m[35;1mInternal Server Error: /handler/image-upload[0m[0m
Traceback (most recent call last):
  File "/Users/chaelee/anaconda3/envs/syu_capstone_2022_1_2/lib/python3.9/site-packages/asgiref/sync.py", line 486, in thread_handler
    raise exc_info[1]
  File "/Users/chaelee/anaconda3/envs/syu_capstone_2022_1_2/lib/python3.9/site-packages/django/core/handlers/exception.py", line 42, in inner
    response = await get_response(request)
  File "/Users/chaelee/anaconda3/envs/syu_capstone_2022_1_2/lib/python3.9/site-packages/django/core/handlers/base.py", line 253, in _get_response_async
    response = await wrapped_callback(
  File "/Users/chaelee/anaconda3/envs/syu_capstone_2022_1_2/lib/python3.9/site-packages/asgiref/sync.py", line 448, in __call__
    ret = await asyncio.wait_for(future, timeout=None)
  File "/Users/chaelee/anaconda3/envs/syu_capstone_2022_1_2/lib/python3.9/asyncio/tasks.py", line 442, in wait_for
    return await fut
  File "/Users/chaelee/anaconda3/envs/syu_capstone_2022_1_2/lib/python3.9/site-packages/asgiref/current_thread_executor.py", line 22, in run
    result = self.fn(*self.args, **self.kwargs)
  File "/Users/chaelee/anaconda3/envs/syu_capstone_2022_1_2/lib/python3.9/site-packages/asgiref/sync.py", line 490, in thread_handler
    return func(*args, **kwargs)
  File "/Users/chaelee/anaconda3/envs/syu_capstone_2022_1_2/lib/python3.9/site-packages/django/views/generic/base.py", line 104, in view
    return self.dispatch(request, *args, **kwargs)
  File "/Users/chaelee/anaconda3/envs/syu_capstone_2022_1_2/lib/python3.9/site-packages/django/views/generic/base.py", line 143, in dispatch
    return handler(request, *args, **kwargs)
  File "/Users/chaelee/anaconda3/envs/syu_capstone_2022_1_2/lib/python3.9/site-packages/django/views/decorators/csrf.py", line 56, in wrapper_view
    return view_func(*args, **kwargs)
  File "/Users/chaelee/PycharmProjects/syu_capstone_2022_1_2/BloomingMind/Handler/views.py", line 49, in post
    data = json.loads(request.body)
  File "/Users/chaelee/anaconda3/envs/syu_capstone_2022_1_2/lib/python3.9/site-packages/django/http/request.py", line 344, in body
    raise RawPostDataException(
django.http.request.RawPostDataException: You cannot access body after reading from request's data stream


20/Apr/2023 19:40:00,935 [ERROR] django.request: [35;1m[35;1mInternal Server Error: /handler/image-upload[0m[0m
Traceback (most recent call last):
  File "/Users/chaelee/anaconda3/envs/syu_capstone_2022_1_2/lib/python3.9/site-packages/asgiref/sync.py", line 486, in thread_handler
    raise exc_info[1]
  File "/Users/chaelee/anaconda3/envs/syu_capstone_2022_1_2/lib/python3.9/site-packages/django/core/handlers/exception.py", line 42, in inner
    response = await get_response(request)
  File "/Users/chaelee/anaconda3/envs/syu_capstone_2022_1_2/lib/python3.9/site-packages/django/core/handlers/base.py", line 253, in _get_response_async
    response = await wrapped_callback(
  File "/Users/chaelee/anaconda3/envs/syu_capstone_2022_1_2/lib/python3.9/site-packages/asgiref/sync.py", line 448, in __call__
    ret = await asyncio.wait_for(future, timeout=None)
  File "/Users/chaelee/anaconda3/envs/syu_capstone_2022_1_2/lib/python3.9/asyncio/tasks.py", line 442, in wait_for
    return await fut
  File "/Users/chaelee/anaconda3/envs/syu_capstone_2022_1_2/lib/python3.9/site-packages/asgiref/current_thread_executor.py", line 22, in run
    result = self.fn(*self.args, **self.kwargs)
  File "/Users/chaelee/anaconda3/envs/syu_capstone_2022_1_2/lib/python3.9/site-packages/asgiref/sync.py", line 490, in thread_handler
    return func(*args, **kwargs)
  File "/Users/chaelee/anaconda3/envs/syu_capstone_2022_1_2/lib/python3.9/site-packages/django/views/generic/base.py", line 104, in view
    return self.dispatch(request, *args, **kwargs)
  File "/Users/chaelee/anaconda3/envs/syu_capstone_2022_1_2/lib/python3.9/site-packages/django/views/generic/base.py", line 143, in dispatch
    return handler(request, *args, **kwargs)
  File "/Users/chaelee/anaconda3/envs/syu_capstone_2022_1_2/lib/python3.9/site-packages/django/views/decorators/csrf.py", line 56, in wrapper_view
    return view_func(*args, **kwargs)
  File "/Users/chaelee/PycharmProjects/syu_capstone_2022_1_2/BloomingMind/Handler/views.py", line 49, in post
    data = json.loads(request.body)
  File "/Users/chaelee/anaconda3/envs/syu_capstone_2022_1_2/lib/python3.9/site-packages/django/http/request.py", line 344, in body
    raise RawPostDataException(
django.http.request.RawPostDataException: You cannot access body after reading from request's data stream


20/Apr/2023 19:44:52,910 [ERROR] django.request: [35;1m[35;1mInternal Server Error: /handler/image-upload[0m[0m
Traceback (most recent call last):
  File "/Users/chaelee/anaconda3/envs/syu_capstone_2022_1_2/lib/python3.9/site-packages/asgiref/sync.py", line 486, in thread_handler
    raise exc_info[1]
  File "/Users/chaelee/anaconda3/envs/syu_capstone_2022_1_2/lib/python3.9/site-packages/django/core/handlers/exception.py", line 42, in inner
    response = await get_response(request)
  File "/Users/chaelee/anaconda3/envs/syu_capstone_2022_1_2/lib/python3.9/site-packages/django/core/handlers/base.py", line 253, in _get_response_async
    response = await wrapped_callback(
  File "/Users/chaelee/anaconda3/envs/syu_capstone_2022_1_2/lib/python3.9/site-packages/asgiref/sync.py", line 448, in __call__
    ret = await asyncio.wait_for(future, timeout=None)
  File "/Users/chaelee/anaconda3/envs/syu_capstone_2022_1_2/lib/python3.9/asyncio/tasks.py", line 442, in wait_for
    return await fut
  File "/Users/chaelee/anaconda3/envs/syu_capstone_2022_1_2/lib/python3.9/site-packages/asgiref/current_thread_executor.py", line 22, in run
    result = self.fn(*self.args, **self.kwargs)
  File "/Users/chaelee/anaconda3/envs/syu_capstone_2022_1_2/lib/python3.9/site-packages/asgiref/sync.py", line 490, in thread_handler
    return func(*args, **kwargs)
  File "/Users/chaelee/anaconda3/envs/syu_capstone_2022_1_2/lib/python3.9/site-packages/django/views/generic/base.py", line 104, in view
    return self.dispatch(request, *args, **kwargs)
  File "/Users/chaelee/anaconda3/envs/syu_capstone_2022_1_2/lib/python3.9/site-packages/django/views/generic/base.py", line 143, in dispatch
    return handler(request, *args, **kwargs)
  File "/Users/chaelee/anaconda3/envs/syu_capstone_2022_1_2/lib/python3.9/site-packages/django/views/decorators/csrf.py", line 56, in wrapper_view
    return view_func(*args, **kwargs)
  File "/Users/chaelee/PycharmProjects/syu_capstone_2022_1_2/BloomingMind/Handler/views.py", line 49, in post
    age = json.loads(request.POST.get('age'))
  File "/Users/chaelee/anaconda3/envs/syu_capstone_2022_1_2/lib/python3.9/json/__init__.py", line 339, in loads
    raise TypeError(f'the JSON object must be str, bytes or bytearray, '
TypeError: the JSON object must be str, bytes or bytearray, not NoneType


20/Apr/2023 19:46:36,807 [ERROR] django.request: [35;1m[35;1mInternal Server Error: /handler/image-upload[0m[0m
Traceback (most recent call last):
  File "/Users/chaelee/anaconda3/envs/syu_capstone_2022_1_2/lib/python3.9/site-packages/asgiref/sync.py", line 486, in thread_handler
    raise exc_info[1]
  File "/Users/chaelee/anaconda3/envs/syu_capstone_2022_1_2/lib/python3.9/site-packages/django/core/handlers/exception.py", line 42, in inner
    response = await get_response(request)
  File "/Users/chaelee/anaconda3/envs/syu_capstone_2022_1_2/lib/python3.9/site-packages/django/core/handlers/base.py", line 253, in _get_response_async
    response = await wrapped_callback(
  File "/Users/chaelee/anaconda3/envs/syu_capstone_2022_1_2/lib/python3.9/site-packages/asgiref/sync.py", line 448, in __call__
    ret = await asyncio.wait_for(future, timeout=None)
  File "/Users/chaelee/anaconda3/envs/syu_capstone_2022_1_2/lib/python3.9/asyncio/tasks.py", line 442, in wait_for
    return await fut
  File "/Users/chaelee/anaconda3/envs/syu_capstone_2022_1_2/lib/python3.9/site-packages/asgiref/current_thread_executor.py", line 22, in run
    result = self.fn(*self.args, **self.kwargs)
  File "/Users/chaelee/anaconda3/envs/syu_capstone_2022_1_2/lib/python3.9/site-packages/asgiref/sync.py", line 490, in thread_handler
    return func(*args, **kwargs)
  File "/Users/chaelee/anaconda3/envs/syu_capstone_2022_1_2/lib/python3.9/site-packages/django/views/generic/base.py", line 104, in view
    return self.dispatch(request, *args, **kwargs)
  File "/Users/chaelee/anaconda3/envs/syu_capstone_2022_1_2/lib/python3.9/site-packages/django/views/generic/base.py", line 143, in dispatch
    return handler(request, *args, **kwargs)
  File "/Users/chaelee/anaconda3/envs/syu_capstone_2022_1_2/lib/python3.9/site-packages/django/views/decorators/csrf.py", line 56, in wrapper_view
    return view_func(*args, **kwargs)
  File "/Users/chaelee/PycharmProjects/syu_capstone_2022_1_2/BloomingMind/Handler/views.py", line 49, in post
    age,gender = request.POST.get('age', 'gender')
ValueError: not enough values to unpack (expected 2, got 1)


20/Apr/2023 20:18:23,244 [ERROR] django.request: [35;1m[35;1mInternal Server Error: /handler/image-upload[0m[0m
Traceback (most recent call last):
  File "/Users/chaelee/anaconda3/envs/syu_capstone_2022_1_2/lib/python3.9/site-packages/asgiref/sync.py", line 486, in thread_handler
    raise exc_info[1]
  File "/Users/chaelee/anaconda3/envs/syu_capstone_2022_1_2/lib/python3.9/site-packages/django/core/handlers/exception.py", line 42, in inner
    response = await get_response(request)
  File "/Users/chaelee/anaconda3/envs/syu_capstone_2022_1_2/lib/python3.9/site-packages/django/core/handlers/base.py", line 253, in _get_response_async
    response = await wrapped_callback(
  File "/Users/chaelee/anaconda3/envs/syu_capstone_2022_1_2/lib/python3.9/site-packages/asgiref/sync.py", line 448, in __call__
    ret = await asyncio.wait_for(future, timeout=None)
  File "/Users/chaelee/anaconda3/envs/syu_capstone_2022_1_2/lib/python3.9/asyncio/tasks.py", line 442, in wait_for
    return await fut
  File "/Users/chaelee/anaconda3/envs/syu_capstone_2022_1_2/lib/python3.9/site-packages/asgiref/current_thread_executor.py", line 22, in run
    result = self.fn(*self.args, **self.kwargs)
  File "/Users/chaelee/anaconda3/envs/syu_capstone_2022_1_2/lib/python3.9/site-packages/asgiref/sync.py", line 490, in thread_handler
    return func(*args, **kwargs)
  File "/Users/chaelee/anaconda3/envs/syu_capstone_2022_1_2/lib/python3.9/site-packages/django/views/generic/base.py", line 104, in view
    return self.dispatch(request, *args, **kwargs)
  File "/Users/chaelee/anaconda3/envs/syu_capstone_2022_1_2/lib/python3.9/site-packages/django/views/generic/base.py", line 143, in dispatch
    return handler(request, *args, **kwargs)
  File "/Users/chaelee/anaconda3/envs/syu_capstone_2022_1_2/lib/python3.9/site-packages/django/views/decorators/csrf.py", line 56, in wrapper_view
    return view_func(*args, **kwargs)
  File "/Users/chaelee/PycharmProjects/syu_capstone_2022_1_2/BloomingMind/Handler/views.py", line 54, in post
    image_save()
  File "/Users/chaelee/PycharmProjects/syu_capstone_2022_1_2/BloomingMind/Handler/views.py", line 68, in image_save
    from ..BloomingMind.settings.base import ROOT_DIR
ImportError: attempted relative import beyond top-level package


20/Apr/2023 20:27:58,021 [ERROR] django.request: [35;1m[35;1mInternal Server Error: /handler/image-upload[0m[0m
Traceback (most recent call last):
  File "/Users/chaelee/anaconda3/envs/syu_capstone_2022_1_2/lib/python3.9/site-packages/asgiref/sync.py", line 486, in thread_handler
    raise exc_info[1]
  File "/Users/chaelee/anaconda3/envs/syu_capstone_2022_1_2/lib/python3.9/site-packages/django/core/handlers/exception.py", line 42, in inner
    response = await get_response(request)
  File "/Users/chaelee/anaconda3/envs/syu_capstone_2022_1_2/lib/python3.9/site-packages/django/core/handlers/base.py", line 253, in _get_response_async
    response = await wrapped_callback(
  File "/Users/chaelee/anaconda3/envs/syu_capstone_2022_1_2/lib/python3.9/site-packages/asgiref/sync.py", line 448, in __call__
    ret = await asyncio.wait_for(future, timeout=None)
  File "/Users/chaelee/anaconda3/envs/syu_capstone_2022_1_2/lib/python3.9/asyncio/tasks.py", line 442, in wait_for
    return await fut
  File "/Users/chaelee/anaconda3/envs/syu_capstone_2022_1_2/lib/python3.9/site-packages/asgiref/current_thread_executor.py", line 22, in run
    result = self.fn(*self.args, **self.kwargs)
  File "/Users/chaelee/anaconda3/envs/syu_capstone_2022_1_2/lib/python3.9/site-packages/asgiref/sync.py", line 490, in thread_handler
    return func(*args, **kwargs)
  File "/Users/chaelee/anaconda3/envs/syu_capstone_2022_1_2/lib/python3.9/site-packages/django/views/generic/base.py", line 104, in view
    return self.dispatch(request, *args, **kwargs)
  File "/Users/chaelee/anaconda3/envs/syu_capstone_2022_1_2/lib/python3.9/site-packages/django/views/generic/base.py", line 143, in dispatch
    return handler(request, *args, **kwargs)
  File "/Users/chaelee/anaconda3/envs/syu_capstone_2022_1_2/lib/python3.9/site-packages/django/views/decorators/csrf.py", line 56, in wrapper_view
    return view_func(*args, **kwargs)
  File "/Users/chaelee/PycharmProjects/syu_capstone_2022_1_2/BloomingMind/Handler/views.py", line 54, in post
    image_save(upload_image)
  File "/Users/chaelee/PycharmProjects/syu_capstone_2022_1_2/BloomingMind/Handler/views.py", line 72, in image_save
    with open(os.path.join(f'{save_path},{image_name}', 'jpg'), 'wb+') as image_write:
FileNotFoundError: [Errno 2] No such file or directory: '/Users/chaelee/PycharmProjects/syu_capstone_2022_1_2/BloomingMind/data/image,fb3d485f-21de-419a-839a-c92df74c5f04/jpg'


20/Apr/2023 20:31:53,562 [ERROR] django.request: [35;1m[35;1mInternal Server Error: /handler/image-upload[0m[0m
Traceback (most recent call last):
  File "/Users/chaelee/anaconda3/envs/syu_capstone_2022_1_2/lib/python3.9/site-packages/asgiref/sync.py", line 486, in thread_handler
    raise exc_info[1]
  File "/Users/chaelee/anaconda3/envs/syu_capstone_2022_1_2/lib/python3.9/site-packages/django/core/handlers/exception.py", line 42, in inner
    response = await get_response(request)
  File "/Users/chaelee/anaconda3/envs/syu_capstone_2022_1_2/lib/python3.9/site-packages/django/core/handlers/base.py", line 253, in _get_response_async
    response = await wrapped_callback(
  File "/Users/chaelee/anaconda3/envs/syu_capstone_2022_1_2/lib/python3.9/site-packages/asgiref/sync.py", line 448, in __call__
    ret = await asyncio.wait_for(future, timeout=None)
  File "/Users/chaelee/anaconda3/envs/syu_capstone_2022_1_2/lib/python3.9/asyncio/tasks.py", line 442, in wait_for
    return await fut
  File "/Users/chaelee/anaconda3/envs/syu_capstone_2022_1_2/lib/python3.9/site-packages/asgiref/current_thread_executor.py", line 22, in run
    result = self.fn(*self.args, **self.kwargs)
  File "/Users/chaelee/anaconda3/envs/syu_capstone_2022_1_2/lib/python3.9/site-packages/asgiref/sync.py", line 490, in thread_handler
    return func(*args, **kwargs)
  File "/Users/chaelee/anaconda3/envs/syu_capstone_2022_1_2/lib/python3.9/site-packages/django/views/generic/base.py", line 104, in view
    return self.dispatch(request, *args, **kwargs)
  File "/Users/chaelee/anaconda3/envs/syu_capstone_2022_1_2/lib/python3.9/site-packages/django/views/generic/base.py", line 143, in dispatch
    return handler(request, *args, **kwargs)
  File "/Users/chaelee/anaconda3/envs/syu_capstone_2022_1_2/lib/python3.9/site-packages/django/views/decorators/csrf.py", line 56, in wrapper_view
    return view_func(*args, **kwargs)
  File "/Users/chaelee/PycharmProjects/syu_capstone_2022_1_2/BloomingMind/Handler/views.py", line 54, in post
    image_save(upload_image)
  File "/Users/chaelee/PycharmProjects/syu_capstone_2022_1_2/BloomingMind/Handler/views.py", line 73, in image_save
    with open(os.path.join(save_path,image_name)) as image_write:
  File "/Users/chaelee/anaconda3/envs/syu_capstone_2022_1_2/lib/python3.9/posixpath.py", line 90, in join
    genericpath._check_arg_types('join', a, *p)
  File "/Users/chaelee/anaconda3/envs/syu_capstone_2022_1_2/lib/python3.9/genericpath.py", line 152, in _check_arg_types
    raise TypeError(f'{funcname}() argument must be str, bytes, or '
TypeError: join() argument must be str, bytes, or os.PathLike object, not 'UUID'


20/Apr/2023 20:32:16,507 [ERROR] django.request: [35;1m[35;1mInternal Server Error: /handler/image-upload[0m[0m
Traceback (most recent call last):
  File "/Users/chaelee/anaconda3/envs/syu_capstone_2022_1_2/lib/python3.9/site-packages/asgiref/sync.py", line 486, in thread_handler
    raise exc_info[1]
  File "/Users/chaelee/anaconda3/envs/syu_capstone_2022_1_2/lib/python3.9/site-packages/django/core/handlers/exception.py", line 42, in inner
    response = await get_response(request)
  File "/Users/chaelee/anaconda3/envs/syu_capstone_2022_1_2/lib/python3.9/site-packages/django/core/handlers/base.py", line 253, in _get_response_async
    response = await wrapped_callback(
  File "/Users/chaelee/anaconda3/envs/syu_capstone_2022_1_2/lib/python3.9/site-packages/asgiref/sync.py", line 448, in __call__
    ret = await asyncio.wait_for(future, timeout=None)
  File "/Users/chaelee/anaconda3/envs/syu_capstone_2022_1_2/lib/python3.9/asyncio/tasks.py", line 442, in wait_for
    return await fut
  File "/Users/chaelee/anaconda3/envs/syu_capstone_2022_1_2/lib/python3.9/site-packages/asgiref/current_thread_executor.py", line 22, in run
    result = self.fn(*self.args, **self.kwargs)
  File "/Users/chaelee/anaconda3/envs/syu_capstone_2022_1_2/lib/python3.9/site-packages/asgiref/sync.py", line 490, in thread_handler
    return func(*args, **kwargs)
  File "/Users/chaelee/anaconda3/envs/syu_capstone_2022_1_2/lib/python3.9/site-packages/django/views/generic/base.py", line 104, in view
    return self.dispatch(request, *args, **kwargs)
  File "/Users/chaelee/anaconda3/envs/syu_capstone_2022_1_2/lib/python3.9/site-packages/django/views/generic/base.py", line 143, in dispatch
    return handler(request, *args, **kwargs)
  File "/Users/chaelee/anaconda3/envs/syu_capstone_2022_1_2/lib/python3.9/site-packages/django/views/decorators/csrf.py", line 56, in wrapper_view
    return view_func(*args, **kwargs)
  File "/Users/chaelee/PycharmProjects/syu_capstone_2022_1_2/BloomingMind/Handler/views.py", line 54, in post
    image_save(upload_image)
  File "/Users/chaelee/PycharmProjects/syu_capstone_2022_1_2/BloomingMind/Handler/views.py", line 73, in image_save
    with open(os.path.join(save_path, str(image_name))) as image_write:
FileNotFoundError: [Errno 2] No such file or directory: '/Users/chaelee/PycharmProjects/syu_capstone_2022_1_2/BloomingMind/data/image/b173efbb-58f5-4f15-8880-62485788af1e'


20/Apr/2023 20:33:27,914 [ERROR] django.request: [35;1m[35;1mInternal Server Error: /handler/image-upload[0m[0m
Traceback (most recent call last):
  File "/Users/chaelee/anaconda3/envs/syu_capstone_2022_1_2/lib/python3.9/site-packages/asgiref/sync.py", line 486, in thread_handler
    raise exc_info[1]
  File "/Users/chaelee/anaconda3/envs/syu_capstone_2022_1_2/lib/python3.9/site-packages/django/core/handlers/exception.py", line 42, in inner
    response = await get_response(request)
  File "/Users/chaelee/anaconda3/envs/syu_capstone_2022_1_2/lib/python3.9/site-packages/django/core/handlers/base.py", line 253, in _get_response_async
    response = await wrapped_callback(
  File "/Users/chaelee/anaconda3/envs/syu_capstone_2022_1_2/lib/python3.9/site-packages/asgiref/sync.py", line 448, in __call__
    ret = await asyncio.wait_for(future, timeout=None)
  File "/Users/chaelee/anaconda3/envs/syu_capstone_2022_1_2/lib/python3.9/asyncio/tasks.py", line 442, in wait_for
    return await fut
  File "/Users/chaelee/anaconda3/envs/syu_capstone_2022_1_2/lib/python3.9/site-packages/asgiref/current_thread_executor.py", line 22, in run
    result = self.fn(*self.args, **self.kwargs)
  File "/Users/chaelee/anaconda3/envs/syu_capstone_2022_1_2/lib/python3.9/site-packages/asgiref/sync.py", line 490, in thread_handler
    return func(*args, **kwargs)
  File "/Users/chaelee/anaconda3/envs/syu_capstone_2022_1_2/lib/python3.9/site-packages/django/views/generic/base.py", line 104, in view
    return self.dispatch(request, *args, **kwargs)
  File "/Users/chaelee/anaconda3/envs/syu_capstone_2022_1_2/lib/python3.9/site-packages/django/views/generic/base.py", line 143, in dispatch
    return handler(request, *args, **kwargs)
  File "/Users/chaelee/anaconda3/envs/syu_capstone_2022_1_2/lib/python3.9/site-packages/django/views/decorators/csrf.py", line 56, in wrapper_view
    return view_func(*args, **kwargs)
  File "/Users/chaelee/PycharmProjects/syu_capstone_2022_1_2/BloomingMind/Handler/views.py", line 54, in post
    image_save(upload_image)
  File "/Users/chaelee/PycharmProjects/syu_capstone_2022_1_2/BloomingMind/Handler/views.py", line 73, in image_save
    with open(os.path.join(save_path, str(image_name) + '.jpg')) as image_write:
FileNotFoundError: [Errno 2] No such file or directory: '/Users/chaelee/PycharmProjects/syu_capstone_2022_1_2/BloomingMind/data/image/898f3e36-4456-4a7a-9053-3c546db748f9.jpg'


20/Apr/2023 21:07:43,170 [ERROR] django.request: [35;1m[35;1mInternal Server Error: /handler/image-upload[0m[0m
Traceback (most recent call last):
  File "/Users/chaelee/PycharmProjects/syu_capstone_2022_1_2/BloomingMind/Handler/views.py", line 52, in post
    image_save(upload_image)
  File "/Users/chaelee/PycharmProjects/syu_capstone_2022_1_2/BloomingMind/Handler/views.py", line 102, in image_save
    for chunk in image_bytes.chunks():
AttributeError: 'bytes' object has no attribute 'chunks'

During handling of the above exception, another exception occurred:

Traceback (most recent call last):
  File "/Users/chaelee/anaconda3/envs/syu_capstone_2022_1_2/lib/python3.9/site-packages/asgiref/sync.py", line 486, in thread_handler
    raise exc_info[1]
  File "/Users/chaelee/anaconda3/envs/syu_capstone_2022_1_2/lib/python3.9/site-packages/django/core/handlers/exception.py", line 42, in inner
    response = await get_response(request)
  File "/Users/chaelee/anaconda3/envs/syu_capstone_2022_1_2/lib/python3.9/site-packages/django/core/handlers/base.py", line 253, in _get_response_async
    response = await wrapped_callback(
  File "/Users/chaelee/anaconda3/envs/syu_capstone_2022_1_2/lib/python3.9/site-packages/asgiref/sync.py", line 448, in __call__
    ret = await asyncio.wait_for(future, timeout=None)
  File "/Users/chaelee/anaconda3/envs/syu_capstone_2022_1_2/lib/python3.9/asyncio/tasks.py", line 442, in wait_for
    return await fut
  File "/Users/chaelee/anaconda3/envs/syu_capstone_2022_1_2/lib/python3.9/site-packages/asgiref/current_thread_executor.py", line 22, in run
    result = self.fn(*self.args, **self.kwargs)
  File "/Users/chaelee/anaconda3/envs/syu_capstone_2022_1_2/lib/python3.9/site-packages/asgiref/sync.py", line 490, in thread_handler
    return func(*args, **kwargs)
  File "/Users/chaelee/anaconda3/envs/syu_capstone_2022_1_2/lib/python3.9/site-packages/django/views/generic/base.py", line 104, in view
    return self.dispatch(request, *args, **kwargs)
  File "/Users/chaelee/anaconda3/envs/syu_capstone_2022_1_2/lib/python3.9/site-packages/django/views/generic/base.py", line 143, in dispatch
    return handler(request, *args, **kwargs)
  File "/Users/chaelee/anaconda3/envs/syu_capstone_2022_1_2/lib/python3.9/site-packages/django/views/decorators/csrf.py", line 56, in wrapper_view
    return view_func(*args, **kwargs)
  File "/Users/chaelee/PycharmProjects/syu_capstone_2022_1_2/BloomingMind/Handler/views.py", line 65, in post
    return JsonResponse(
  File "/Users/chaelee/anaconda3/envs/syu_capstone_2022_1_2/lib/python3.9/site-packages/django/http/response.py", line 748, in __init__
    data = json.dumps(data, cls=encoder, **json_dumps_params)
  File "/Users/chaelee/anaconda3/envs/syu_capstone_2022_1_2/lib/python3.9/json/__init__.py", line 234, in dumps
    return cls(
  File "/Users/chaelee/anaconda3/envs/syu_capstone_2022_1_2/lib/python3.9/json/encoder.py", line 199, in encode
    chunks = self.iterencode(o, _one_shot=True)
  File "/Users/chaelee/anaconda3/envs/syu_capstone_2022_1_2/lib/python3.9/json/encoder.py", line 257, in iterencode
    return _iterencode(o, 0)
  File "/Users/chaelee/anaconda3/envs/syu_capstone_2022_1_2/lib/python3.9/site-packages/django/core/serializers/json.py", line 106, in default
    return super().default(o)
  File "/Users/chaelee/anaconda3/envs/syu_capstone_2022_1_2/lib/python3.9/json/encoder.py", line 179, in default
    raise TypeError(f'Object of type {o.__class__.__name__} '
TypeError: Object of type set is not JSON serializable


20/Apr/2023 21:35:40,959 [ERROR] django.request: [35;1m[35;1mInternal Server Error: /handler/image-upload[0m[0m
Traceback (most recent call last):
  File "/Users/chaelee/PycharmProjects/syu_capstone_2022_1_2/BloomingMind/Handler/views.py", line 51, in post
    image_save(upload_image)
  File "/Users/chaelee/PycharmProjects/syu_capstone_2022_1_2/BloomingMind/Handler/views.py", line 97, in image_save
    if ['jpeg,jpg'] not in upload_image.name:
TypeError: 'in <string>' requires string as left operand, not list

During handling of the above exception, another exception occurred:

Traceback (most recent call last):
  File "/Users/chaelee/anaconda3/envs/syu_capstone_2022_1_2/lib/python3.9/site-packages/asgiref/sync.py", line 486, in thread_handler
    raise exc_info[1]
  File "/Users/chaelee/anaconda3/envs/syu_capstone_2022_1_2/lib/python3.9/site-packages/django/core/handlers/exception.py", line 42, in inner
    response = await get_response(request)
  File "/Users/chaelee/anaconda3/envs/syu_capstone_2022_1_2/lib/python3.9/site-packages/django/core/handlers/base.py", line 253, in _get_response_async
    response = await wrapped_callback(
  File "/Users/chaelee/anaconda3/envs/syu_capstone_2022_1_2/lib/python3.9/site-packages/asgiref/sync.py", line 448, in __call__
    ret = await asyncio.wait_for(future, timeout=None)
  File "/Users/chaelee/anaconda3/envs/syu_capstone_2022_1_2/lib/python3.9/asyncio/tasks.py", line 442, in wait_for
    return await fut
  File "/Users/chaelee/anaconda3/envs/syu_capstone_2022_1_2/lib/python3.9/site-packages/asgiref/current_thread_executor.py", line 22, in run
    result = self.fn(*self.args, **self.kwargs)
  File "/Users/chaelee/anaconda3/envs/syu_capstone_2022_1_2/lib/python3.9/site-packages/asgiref/sync.py", line 490, in thread_handler
    return func(*args, **kwargs)
  File "/Users/chaelee/anaconda3/envs/syu_capstone_2022_1_2/lib/python3.9/site-packages/django/views/generic/base.py", line 104, in view
    return self.dispatch(request, *args, **kwargs)
  File "/Users/chaelee/anaconda3/envs/syu_capstone_2022_1_2/lib/python3.9/site-packages/django/views/generic/base.py", line 143, in dispatch
    return handler(request, *args, **kwargs)
  File "/Users/chaelee/anaconda3/envs/syu_capstone_2022_1_2/lib/python3.9/site-packages/django/views/decorators/csrf.py", line 56, in wrapper_view
    return view_func(*args, **kwargs)
  File "/Users/chaelee/PycharmProjects/syu_capstone_2022_1_2/BloomingMind/Handler/views.py", line 64, in post
    return JsonResponse(
  File "/Users/chaelee/anaconda3/envs/syu_capstone_2022_1_2/lib/python3.9/site-packages/django/http/response.py", line 748, in __init__
    data = json.dumps(data, cls=encoder, **json_dumps_params)
  File "/Users/chaelee/anaconda3/envs/syu_capstone_2022_1_2/lib/python3.9/json/__init__.py", line 234, in dumps
    return cls(
  File "/Users/chaelee/anaconda3/envs/syu_capstone_2022_1_2/lib/python3.9/json/encoder.py", line 199, in encode
    chunks = self.iterencode(o, _one_shot=True)
  File "/Users/chaelee/anaconda3/envs/syu_capstone_2022_1_2/lib/python3.9/json/encoder.py", line 257, in iterencode
    return _iterencode(o, 0)
  File "/Users/chaelee/anaconda3/envs/syu_capstone_2022_1_2/lib/python3.9/site-packages/django/core/serializers/json.py", line 106, in default
    return super().default(o)
  File "/Users/chaelee/anaconda3/envs/syu_capstone_2022_1_2/lib/python3.9/json/encoder.py", line 179, in default
    raise TypeError(f'Object of type {o.__class__.__name__} '
TypeError: Object of type set is not JSON serializable


20/Apr/2023 21:37:25,858 [ERROR] django.request: [35;1m[35;1mInternal Server Error: /handler/image-upload[0m[0m
Traceback (most recent call last):
  File "/Users/chaelee/PycharmProjects/syu_capstone_2022_1_2/BloomingMind/Handler/views.py", line 51, in post
    image_save(upload_image)
  File "/Users/chaelee/PycharmProjects/syu_capstone_2022_1_2/BloomingMind/Handler/views.py", line 97, in image_save
    if ['jp'] not in upload_image.name:
TypeError: 'in <string>' requires string as left operand, not list

During handling of the above exception, another exception occurred:

Traceback (most recent call last):
  File "/Users/chaelee/anaconda3/envs/syu_capstone_2022_1_2/lib/python3.9/site-packages/asgiref/sync.py", line 486, in thread_handler
    raise exc_info[1]
  File "/Users/chaelee/anaconda3/envs/syu_capstone_2022_1_2/lib/python3.9/site-packages/django/core/handlers/exception.py", line 42, in inner
    response = await get_response(request)
  File "/Users/chaelee/anaconda3/envs/syu_capstone_2022_1_2/lib/python3.9/site-packages/django/core/handlers/base.py", line 253, in _get_response_async
    response = await wrapped_callback(
  File "/Users/chaelee/anaconda3/envs/syu_capstone_2022_1_2/lib/python3.9/site-packages/asgiref/sync.py", line 448, in __call__
    ret = await asyncio.wait_for(future, timeout=None)
  File "/Users/chaelee/anaconda3/envs/syu_capstone_2022_1_2/lib/python3.9/asyncio/tasks.py", line 442, in wait_for
    return await fut
  File "/Users/chaelee/anaconda3/envs/syu_capstone_2022_1_2/lib/python3.9/site-packages/asgiref/current_thread_executor.py", line 22, in run
    result = self.fn(*self.args, **self.kwargs)
  File "/Users/chaelee/anaconda3/envs/syu_capstone_2022_1_2/lib/python3.9/site-packages/asgiref/sync.py", line 490, in thread_handler
    return func(*args, **kwargs)
  File "/Users/chaelee/anaconda3/envs/syu_capstone_2022_1_2/lib/python3.9/site-packages/django/views/generic/base.py", line 104, in view
    return self.dispatch(request, *args, **kwargs)
  File "/Users/chaelee/anaconda3/envs/syu_capstone_2022_1_2/lib/python3.9/site-packages/django/views/generic/base.py", line 143, in dispatch
    return handler(request, *args, **kwargs)
  File "/Users/chaelee/anaconda3/envs/syu_capstone_2022_1_2/lib/python3.9/site-packages/django/views/decorators/csrf.py", line 56, in wrapper_view
    return view_func(*args, **kwargs)
  File "/Users/chaelee/PycharmProjects/syu_capstone_2022_1_2/BloomingMind/Handler/views.py", line 64, in post
    return JsonResponse(
  File "/Users/chaelee/anaconda3/envs/syu_capstone_2022_1_2/lib/python3.9/site-packages/django/http/response.py", line 748, in __init__
    data = json.dumps(data, cls=encoder, **json_dumps_params)
  File "/Users/chaelee/anaconda3/envs/syu_capstone_2022_1_2/lib/python3.9/json/__init__.py", line 234, in dumps
    return cls(
  File "/Users/chaelee/anaconda3/envs/syu_capstone_2022_1_2/lib/python3.9/json/encoder.py", line 199, in encode
    chunks = self.iterencode(o, _one_shot=True)
  File "/Users/chaelee/anaconda3/envs/syu_capstone_2022_1_2/lib/python3.9/json/encoder.py", line 257, in iterencode
    return _iterencode(o, 0)
  File "/Users/chaelee/anaconda3/envs/syu_capstone_2022_1_2/lib/python3.9/site-packages/django/core/serializers/json.py", line 106, in default
    return super().default(o)
  File "/Users/chaelee/anaconda3/envs/syu_capstone_2022_1_2/lib/python3.9/json/encoder.py", line 179, in default
    raise TypeError(f'Object of type {o.__class__.__name__} '
TypeError: Object of type set is not JSON serializable
